Workbook
Name ESTIMATEUR: 'SOMM. T.OFF'!$A$69:$A$72
Name ESTIMATEUR: 'SOMM. T.OFF'!$A$69:$A$72

Sheet ESTIMÉ
A1: PROJET | H1: Estimé no. | K1: Page : 1 de 2 | L1: PROJET | M1: =IF(B1="","",B1) | R1: Estimé no. | T1: =IF(I1="","",I1) | V1: Page: 2 de 2
H2: Date fermeture | L2: CONDUITS RECTANGULAIRES | X2: Calcul Sismique
A3: Adresse | H3: Plans | L3: FABRICATION | P3: SUSPENSION | R3: INSTALLATION
A4: INGÉNIEUR | H4: Section devis | L4: TYPES | M4: LBS | N4: PIEDS | O4: COÛT | P4: QTÉ | Q4: COÛT | R4: GENRE | S4: Pi | T4: Pi/J | U4: HRES | V4: COÛT
A5: ARCHITECTE | L5: BASSE PRESSION | M5: =IF('SOMM. T.OFF'!B14="","",'SOMM. T.OFF'!B14) -> 0 | N5: =IF('SOMM. T.OFF'!C14="","",'SOMM. T.OFF'!C14) -> 0 | O5: =IF(M5="",0,M5*DONNÉES!C16) -> 0 | Q5: =IF(P5="",N5*DONNÉES!D16,P5*DONNÉES!E16) -> 0 | R5: SM (Salle mé) | S5: =IF('SOMM. T.OFF'!F14="",0,'SOMM. T.OFF'!F14) -> 0 | T5: =IF(S5=0,0,"") -> 0 | U5: =IF(S5=0,0,S5/T5*8) -> 0 | V5: =IF(T5="","",U5*DONNÉES!$E$12) -> 0 | X5: Équipement | Y5: Qté | Z5: Prix | AA5: Total
A6: PROPRIÉTAIRE | H6: Addenda | L6: MOYENNE PRESSION | M6: =IF('SOMM. T.OFF'!B15="","",'SOMM. T.OFF'!B15) -> 0 | N6: =IF('SOMM. T.OFF'!C15="","",'SOMM. T.OFF'!C15) -> 0 | O6: =IF(M6="",0,M6*DONNÉES!C17) -> 0 | Q6: =IF(P6="",N6*DONNÉES!D17,P6*DONNÉES!E17) -> 0 | R6: HA (30" et -) | S6: =IF('SOMM. T.OFF'!F15="",0,'SOMM. T.OFF'!F15) -> 0 | T6: =IF(S6=0,0,"") -> 0 | U6: =IF(S6=0,0,S6/T6*8) -> 0 | V6: =IF(T6="","",U6*DONNÉES!$E$12) -> 0 | X6: Rapport (nbr visite) | Y6: 1 | Z6: 750 | AA6: =Z6*Y6 -> 750
A7: ESTIMATEUR | H7: Échéancier | L7: HAUTE PRESSION | M7: =IF('SOMM. T.OFF'!B16="","",'SOMM. T.OFF'!B16) -> 0 | N7: =IF('SOMM. T.OFF'!C16="","",'SOMM. T.OFF'!C16) -> 0 | O7: =IF(M7="",0,M7*DONNÉES!C18) -> 0 | Q7: =IF(P7="",N7*DONNÉES!D18,P7*DONNÉES!E18) -> 0 | R7: RI (Riser/SP) | S7: =IF('SOMM. T.OFF'!F16="",0,'SOMM. T.OFF'!F16) -> 0 | T7: =IF(S7=0,0,"") -> 0 | U7: =IF(S7=0,0,S7/T7*8) -> 0 | V7: =IF(T7="","",U7*DONNÉES!$E$12) -> 0 | X7: Centrales d'air | Z7: 500 | AA7: =Z7*Y7 -> 0
A8: ÉQUIPEMENTS | L8: 16 GA | M8: =IF('SOMM. T.OFF'!B17="","",'SOMM. T.OFF'!B17) -> 0 | N8: =IF('SOMM. T.OFF'!C17="","",'SOMM. T.OFF'!C17) -> 0 | O8: =IF(M8="",0,M8*DONNÉES!C19) -> 0 | Q8: =IF(P8="",N8*DONNÉES!D19,P8*DONNÉES!E19) -> 0 | R8: 16 (16ga/SS) | S8: =IF('SOMM. T.OFF'!F18="",0,'SOMM. T.OFF'!F18) -> 0 | T8: =IF(S8=0,0,"") -> 0 | U8: =IF(S8=0,0,S8/T8*8) -> 0 | V8: =IF(T8="","",U8*DONNÉES!$E$12) -> 0 | X8: Unité au toit | Z8: 250 | AA8: =Z8*Y8 -> 0
A9: DESCRIPTION | C9: TAG | D9: SPECS | E9: DEVIS | F9: QTÉ | G9: HRES | H9: ACCESSOIRES | I9: COÛT INSTAL. | J9: MAT'L ESTIMÉ | K9: MAT'L RÉEL | L9: ALUMINIUM | M9: =IF('SOMM. T.OFF'!B18="","",'SOMM. T.OFF'!B18) -> 0 | N9: =IF('SOMM. T.OFF'!C18="","",'SOMM. T.OFF'!C18) -> 0 | O9: =IF(M9="",0,M9*DONNÉES!C20) -> 0 | Q9: =IF(P9="",N9*DONNÉES!D20,P9*DONNÉES!E20) -> 0 | R9: AL (Alumi) | S9: =IF('SOMM. T.OFF'!F19="",0,'SOMM. T.OFF'!F19) -> 0 | T9: =IF(S9=0,0,"") -> 0 | U9: =IF(S9=0,0,S9/T9*8) -> 0 | V9: =IF(T9="","",U9*DONNÉES!$E$12) -> 0 | X9: Centrale au toit | Z9: 500 | AA9: =Z9*Y9 -> 0
A10: UNITÉ DE CLIM. | H10: =IF(F10=0,0,"") -> 0 | I10: =IF(G10=0,0,G10*DONNÉES!$E$12) -> 0 | J10: =IF(E10=0,0,"") -> 0 | K10: =IF(E10=0,0,"") -> 0 | L10: ACIER INOXYDABLE | M10: =IF('SOMM. T.OFF'!B19="","",'SOMM. T.OFF'!B19) -> 0 | N10: =IF('SOMM. T.OFF'!C19="","",'SOMM. T.OFF'!C19) -> 0 | O10: =IF(M10="",0,M10*DONNÉES!C21) -> 0 | Q10: =IF(P10="",N10*DONNÉES!D21,P10*DONNÉES!E21) -> 0 | R10: RE (31" et +) | S10: =IF('SOMM. T.OFF'!F17="",0,'SOMM. T.OFF'!F17) -> 0 | T10: 0 | U10: =IF(S10=0,0,S10/T10*8) -> 0 | V10: =IF(T10="","",U10*DONNÉES!$E$12) -> 0 | X10: Condenseur | Z10: 80 | AA10: =Z10*Y10 -> 0
A11: BASE DE TOIT | H11: =IF(F11=0,0,"") -> 0 | I11: =IF(G11=0,0,G11*DONNÉES!$E$12) -> 0 | J11: =IF(E11=0,0,"") -> 0 | K11: =IF(E11=0,0,"") -> 0 | M11: =IF('SOMM. T.OFF'!B20="","",'SOMM. T.OFF'!B20) -> 0 | N11: =IF('SOMM. T.OFF'!C20="","",'SOMM. T.OFF'!C20) -> 0 | O11: =IF(M11="",0,M11*DONNÉES!C22) -> 0 | Q11: =IF(P11="",N11*DONNÉES!D22,P11*DONNÉES!E22) -> 0 | S11: =IF('SOMM. T.OFF'!F20="","",'SOMM. T.OFF'!F20) -> 0 | T11: =IF(S11=0,0,"") -> 0 | U11: =IF(S11=0,0,S11/T11*8) -> 0 | V11: =IF(T11="","",U11*DONNÉES!$E$12) -> 0 | X11: Thermopompe (intérieur) | Z11: 80 | AA11: =Z11*Y11 -> 0
A12: UNITÉ DE COND. | H12: =IF(F12=0,0,"") -> 0 | I12: =IF(G12=0,0,G12*DONNÉES!$E$12) -> 0 | J12: =IF(E12=0,0,"") -> 0 | K12: =IF(E12=0,0,"") -> 0 | L12: SOUDURE (atelier) | M12: HEURES--> | O12: =N12*DONNÉES!E26 -> 0 | R12: Soudure | V12: =U12*DONNÉES!$E$25 -> 0 | X12: Fancoil | Z12: 80 | AA12: =Z12*Y12 -> 0
A13: ÉVAPORATEUR | H13: =IF(F13=0,0,"") -> 0 | I13: =IF(G13=0,0,G13*DONNÉES!$E$12) -> 0 | J13: =IF(E13=0,0,"") -> 0 | K13: =IF(E13=0,0,"") -> 0 | L13: SOUS-TOTAL | M13: =SUM(M5:M11) -> 0 | N13: =SUM(N5:N11) -> 0 | O13: =SUM(O5:O12) -> 0 | Q13: =SUM(Q5:Q11) -> 0 | U13: =SUM(U5:U11) -> 0 | V13: =SUM(V5:V12) -> 0 | X13: Buse d'humidificateur | Z13: 50 | AA13: =Z13*Y13 -> 0
A14: UNITÉ DE VENTI. INT. | H14: =IF(F14=0,0,"") -> 0 | I14: =IF(G14=0,0,G14*DONNÉES!$E$12) -> 0 | J14: =IF(E14=0,0,"") -> 0 | K14: =IF(E14=0,0,"") -> 0 | X14: Boites | Z14: 25 | AA14: =Z14*Y14 -> 0
A15: UNITÉ DE RÉCUP. | H15: =IF(F15=0,0,"") -> 0 | I15: =IF(G15=0,0,G15*DONNÉES!$E$12) -> 0 | J15: =IF(E15=0,0,"") -> 0 | K15: =IF(E15=0,0,"") -> 0 | L15: CONDUITS SPIRALS | X15: Diffuseurs | Z15: 3 | AA15: =Z15*Y15 -> 0
A16: BASE DE TOIT | H16: =IF(F16=0,0,"") -> 0 | I16: =IF(G16=0,0,G16*DONNÉES!$E$12) -> 0 | J16: =IF(E16=0,0,"") -> 0 | K16: =IF(E16=0,0,"") -> 0 | L16: CONDUITS | N16: JOINTS | P16: SUSPENSION | R16: INSTALLATION | X16: Ventilateur toit | Z16: 15 | AA16: =Z16*Y16 -> 0
A17: UNITÉ D'AIR NEUF | H17: =IF(F17=0,0,"") -> 0 | I17: =IF(G17=0,0,G17*DONNÉES!$E$12) -> 0 | J17: =IF(E17=0,0,"") -> 0 | K17: =IF(E17=0,0,"") -> 0 | L17: TYPES | M17: PIEDS | N17: QTÉ | O17: COÛT | P17: QTÉ | Q17: COÛT | R17: GENRE | S17: Pi | T17: Pi/J | U17: HRES | V17: COÛT | X17: Ventilateur cabinet | Z17: 80 | AA17: =Z17*Y17 -> 0
A18: BASE DE TOIT | H18: =IF(F18=0,0,"") -> 0 | I18: =IF(G18=0,0,G18*DONNÉES!$E$12) -> 0 | J18: =IF(E18=0,0,"") -> 0 | K18: =IF(E18=0,0,"") -> 0 | L18: BASSE PRESSION | O18: =N18*DONNÉES!E34 -> 0 | Q18: =M18*DONNÉES!E47 -> 0 | R18: 16" et - | S18: =SPIRALE!T23 -> 0 | T18: =IF(S18=0,1,"??") -> 1 | U18: =IF(S18="","",S18/T18*8) -> 0 | V18: =IF(T18="",0,U18*DONNÉES!$E$12) -> 0 | X18: Gros ventilateur | Z18: 150 | AA18: =Z18*Y18 -> 0
A19: UNITÉ DE DÉHUMID. | H19: =IF(F19=0,0,"") -> 0 | I19: =IF(G19=0,0,G19*DONNÉES!$E$12) -> 0 | J19: =IF(E19=0,0,"") -> 0 | K19: =IF(E19=0,0,"") -> 0 | L19: MOYENNE PRESSION | O19: =N19*DONNÉES!E35 -> 0 | Q19: =IF(P19="",M19*DONNÉES!E33,P19*DONNÉES!E32) -> 0 | R19: 18" et + | S19: =SPIRALE!T24 -> 0 | T19: =IF(S19=0,1,"??") -> 1 | U19: =IF(S19="","",S19/T19*8) -> 0 | V19: =IF(T19="",0,U19*DONNÉES!$E$12) -> 0 | X19: Ventilateur strobic | Z19: 350 | AA19: =Z19*Y19 -> 0
A20: BASE DE TOIT | H20: =IF(F20=0,0,"") -> 0 | I20: =IF(G20=0,0,G20*DONNÉES!$E$12) -> 0 | J20: =IF(E20=0,0,"") -> 0 | K20: =IF(E20=0,0,"") -> 0 | L20: HAUTE PRESSION | O20: =N20*DONNÉES!E36 -> 0 | Q20: =IF(P20="",M20*DONNÉES!E33,P20*DONNÉES!E32) -> 0 | U20: =IF(S20="","",S20/T20*8) | V20: =IF(T20="",0,U20*DONNÉES!$E$12) -> 0 | X20: Section filtre | Z20: 50 | AA20: =Z20*Y20 -> 0
A21: VENTILATEUR CABINET | H21: =IF(F21=0,0,"") -> 0 | I21: =IF(G21=0,0,G21*DONNÉES!$E$12) -> 0 | J21: =IF(E21=0,0,"") -> 0 | K21: =IF(E21=0,0,"") -> 0 | O21: =N21*DONNÉES!E37 -> 0 | Q21: =IF(P21="",M21*DONNÉES!E33,P21*DONNÉES!E32) -> 0 | U21: =IF(S21="","",S21/T21*8) | V21: =IF(T21="",0,U21*DONNÉES!$E$12) -> 0 | X21: Silencieux | Z21: 50 | AA21: =Z21*Y21 -> 0
A22: VENTILATEUR DE TOIT | H22: =IF(F22=0,0,"") -> 0 | I22: =IF(G22=0,0,G22*DONNÉES!$E$12) -> 0 | J22: =IF(E22=0,0,"") -> 0 | K22: =IF(E22=0,0,"") -> 0 | M22: SOUS-TOTAL | O22: =SUM(O18:O21) -> 0 | Q22: =SUM(Q18:Q21) -> 0 | R22: SOUDURE | S22: HEURES---> | V22: =U22*DONNÉES!E25 -> 0 | X22: Conduits 6 pi.ca. et + (au 20') | Z22: 300 | AA22: =Z22*Y22 -> 0
A23: BASE DE TOIT | H23: =IF(F23=0,0,"") -> 0 | I23: =IF(G23=0,0,G23*DONNÉES!$E$12) -> 0 | J23: =IF(E23=0,0,"") -> 0 | K23: =IF(E23=0,0,"") -> 0 | M23: COÛT CONDUITS & FITTINGS | P23: =SPIRALE!$F$6 -> 0 | R23: SOUS-TOTAL | U23: =SUM(U15:U22) -> 0 | V23: =SUM(V15:V22) -> 0 | X23: Autres Équipements | Z23: 500 | AA23: =Z23*Y23 -> 0
A24: VENTILATEUR TOILETTE | H24: =IF(F24=0,0,"") -> 0 | I24: =IF(G24=0,0,G24*DONNÉES!$E$12) -> 0 | J24: =IF(E24=0,0,"") -> 0 | K24: =IF(E24=0,0,"") -> 0
A25: HUMIDIFICATEUR | H25: =IF(F25=0,0,"") -> 0 | I25: =IF(G25=0,0,G25*DONNÉES!$E$12) -> 0 | J25: =IF(E25=0,0,"") -> 0 | K25: =IF(E25=0,0,"") -> 0
A26: SERPENTINS ÉLECTRIQUES | H26: =IF(F26=0,0,"") -> 0 | I26: =IF(G26=0,0,G26*DONNÉES!$E$12) -> 0 | J26: =IF(E26=0,0,"") -> 0 | K26: =IF(E26=0,0,"") -> 0
A27: SERPENTINS | H27: =IF(F27=0,0,"") -> 0 | I27: =IF(G27=0,0,G27*DONNÉES!$E$12) -> 0 | J27: =IF(E27=0,0,"") -> 0 | K27: =IF(E27=0,0,"") -> 0
A28: HOTTE COMMERCIALE | H28: =IF(F28=0,0,"") -> 0 | I28: =IF(G28=0,0,G28*DONNÉES!$E$12) -> 0 | J28: =IF(E28=0,0,"") -> 0 | K28: =IF(E28=0,0,"") -> 0
A29: HOTTE RÉSIDENTIELLE | H29: =IF(F29=0,0,"") -> 0 | I29: =IF(G29=0,0,G29*DONNÉES!$E$12) -> 0 | J29: =IF(E29=0,0,"") -> 0 | K29: =IF(E29=0,0,"") -> 0
A30: BOÎTES | H30: =IF(F30=0,0,"") -> 0 | I30: =IF(G30=0,0,G30*DONNÉES!$E$12) -> 0 | J30: =IF(E30=0,0,"") -> 0 | K30: =IF(E30=0,0,"") -> 0 | X30: Autres Équipements | Z30: 250 | AA30: =Z30*Y30 -> 0
A31: GRILLES ET DIFFUSEURS | H31: 0 | I31: =IF(G31=0,0,G31*DONNÉES!$E$12) -> 0 | J31: =IF(E31=0,0,"") -> 0 | K31: =IF(E31=0,0,"") -> 0 | L31: ISOLANT ACOUSTIQUE | P31: ACCESSOIRES - CONDUITS | X31: Autres Équipements | Z31: 100 | AA31: =Z31*Y31 -> 0
A32: PLENUMS | H32: 0 | I32: =IF(G32=0,0,G32*DONNÉES!$E$12) -> 0 | J32: =IF(E32=0,0,"") -> 0 | K32: =IF(E32=0,0,"") -> 0 | L32: TYPE | N32: PI. CAR. | O32: COUT | P32: DESCRIPTION | U32: QTE | V32: COUT | X32: Autres Équipements | Z32: 50 | AA32: =Z32*Y32 -> 0
A33: PERSIENNES | H33: =IF(F33=0,0,"") -> 0 | I33: =IF(G33=0,0,G33*DONNÉES!$E$12) -> 0 | J33: =IF(E33=0,0,"") -> 0 | K33: =IF(E33=0,0,"") -> 0 | L33: 1/2" FLEXIBLE | N33: =IF('SOMM. T.OFF'!D32="","",'SOMM. T.OFF'!D32) -> 0 | O33: =N33*DONNÉES!E27 -> 0 | P33: CANEVAS (pi) | R33: 4"-4"-4" ST | U33: =IF('SOMM. T.OFF'!H49=0,0,'SOMM. T.OFF'!H49) -> 0 | V33: =U33*DONNÉES!I12 -> 0 | AA33: =Z33*Y33 -> 0
A34: CABANONS | H34: =IF(F34=0,0,"") -> 0 | I34: =IF(G34=0,0,G34*DONNÉES!$E$12) -> 0 | J34: =IF(E34=0,0,"") -> 0 | K34: =IF(E34=0,0,"") -> 0 | L34: 1" FLEXIBLE | N34: =IF('SOMM. T.OFF'!D33="","",'SOMM. T.OFF'!D33) -> 0 | O34: =N34*DONNÉES!E28 -> 0 | R34: 4''-4''-4'' XL | U34: =IF('SOMM. T.OFF'!H50=0,0,'SOMM. T.OFF'!H50) -> 0 | V34: =U34*DONNÉES!I13 -> 0 | AA34: =Z34*Y34 -> 0
A35: SORTIES MURALES | H35: =IF(F35=0,0,"") -> 0 | I35: =IF(G35=0,0,G35*DONNÉES!$E$12) -> 0 | J35: =IF(E35=0,0,"") -> 0 | K35: =IF(E35=0,0,"") -> 0 | L35: 1" RIGIDE | N35: =IF('SOMM. T.OFF'!D34="","",'SOMM. T.OFF'!D34) -> 0 | O35: =N35*DONNÉES!E29 -> 0 | P35: GRILLAGE (pi.car.) | R35: SANS CADRE | U35: =IF('SOMM. T.OFF'!F58="",0,'SOMM. T.OFF'!F58) -> 0 | V35: =U35*DONNÉES!I14 -> 0 | AA35: =Z35*Y35 -> 0
A36: VOLETS COUPE-FEU | F36: =IF('SOMM. T.OFF'!E52=0,0,'SOMM. T.OFF'!E52) -> 0 | H36: 0 | I36: =IF(G36=0,0,G36*DONNÉES!$E$12) -> 0 | J36: =IF(E36=0,0,"") -> 0 | K36: =IF(E36=0,0,"") -> 0 | L36: 2" | N36: =IF('SOMM. T.OFF'!D35="","",'SOMM. T.OFF'!D35) -> 0 | O36: =N36*DONNÉES!E30 -> 0 | R36: AVEC CADRE | U36: =IF('SOMM. T.OFF'!F59="",0,'SOMM. T.OFF'!F59) -> 0 | V36: =U36*DONNÉES!I15 -> 0 | AA36: =Z36*Y36 -> 0
A37: VOLETS COUPE-FEU/FUMÉE | F37: ='SOMM. T.OFF'!E62 -> 0 | H37: 0 | I37: =IF(G37=0,0,G37*DONNÉES!$E$12) -> 0 | J37: =IF(E37=0,0,"") -> 0 | K37: =IF(E37=0,0,"") -> 0 | M37: SOUS-TOTAL | O37: =SUM(O33:O36) -> 0 | P37: VOLETS MANUELS TUYAUX CHAUFFAGE (unitaire) | U37: =IF('SOMM. T.OFF'!E51=0,0,'SOMM. T.OFF'!E51) -> 0 | V37: =U37*DONNÉES!I16 -> 0 | Y37: GRAND TOTAL | AA37: =SUM(AA6:AA36) -> 750
A38: VOLETS MOTORISÉS | F38: =IF(AND('SOMM. T.OFF'!E53,'SOMM. T.OFF'!E54,0),0,'SOMM. T.OFF'!E53+'SOMM. T.OFF'!E54) -> 0 | H38: 0 | I38: =IF(G38=0,0,G38*DONNÉES!$E$12) -> 0 | J38: =IF(E38=0,0,('SOMM. T.OFF'!F53*DONNÉES!I34)+('SOMM. T.OFF'!F54*DONNÉES!I35)) -> 0 | K38: =IF(E38=0,0,"") -> 0 | P38: SIDE TAKE-OFF C/A SPLITTER (unitaire) | U38: =IF('SOMM. T.OFF'!E60=0,0,'SOMM. T.OFF'!E60) -> 0 | V38: =U38*DONNÉES!I17 -> 0
A39: ACTUATEUR | H39: 0 | I39: =IF(G39=0,0,G39*DONNÉES!$E$12) -> 0 | J39: =IF(E39=0,0,"") -> 0 | K39: =IF(E39=0,0,"") -> 0 | L39: MAIN D'OEUVRE - DIVERS | P39: T. VANES (pi.car.) | R39: SIMPLE | U39: =IF('SOMM. T.OFF'!F47=0,0,'SOMM. T.OFF'!F47) -> 0 | V39: =U39*DONNÉES!I18 -> 0 | X39: Calul Dessins
A40: FILTRES | H40: =IF(F40=0,0,"") -> 0 | I40: =IF(G40=0,0,G40*DONNÉES!$E$12) -> 0 | J40: =IF(E40=0,0,"") -> 0 | K40: =IF(E40=0,0,"") -> 0 | L40: DESCRIPTION | N40: HRES | O40: COUT | R40: DOUBLE | U40: =IF('SOMM. T.OFF'!F48=0,0,'SOMM. T.OFF'!F48) -> 0 | V40: =U40*DONNÉES!I19 -> 0
...

Sheet TAKE OFF
A1: PROJET : | C1: =IF(ESTIMÉ!B1="","",ESTIMÉ!B1) | L1: SYSTÈME :
A3: CODES - ACCESOIRES | L3: CALIBRE DE TÔLE
A4: 1/2" ACOUSTIQUE | C4: 1 | D4: V. MAN. TUYAUX CHAUFFAGE | I4: 9 | L4: METRIQUE | N4: M | O4: ANGLAIS
A5: 1" ACOUST. FLEX. | C5: 2 | D5: VCF - MANCHONS - UNITAIRE | I5: 10 | L5: 0 | M5: 305 | N5: 26 | O5: 0 | P5: 12
A6: 1" ACOUST. RIG. | C6: 21 | D6: VCF - COUPE-FUMÉE | I6: 100 | L6: 310 | M6: 750 | N6: 24 | O6: 13 | P6: 30
A7: 2" ACOUSTIQUE | C7: 3 | D7: V. MOTORISÉ | I7: 11 | L7: 755 | M7: 1500 | N7: 22 | O7: 31 | P7: 59
A8: 1" THERMIQUE | C8: 4 | D8: V. MOTORISÉ ISOLÉ | I8: 111 | L8: 1505 | M8: 2100 | N8: 20 | O8: 60 | P8: 82
A9: 2" THERMIQUE | C9: 5 | D9: V. GRAVITÉ | I9: 12 | L9: 2105 | M9: &plus | N9: 18 | O9: 83 | P9: &plus
A10: ACIER 16 GA | C10: 6 | D10: V. MANUEL 30" ET - UNITAIRE | I10: 13 | L10: TYPE & INSTALLATION
A11: ALUMINIUM | C11: 61 | D11: V. MANUEL CADRE 31" ET + | I11: 131 | L11: B. PRESSION | M11: BP | N11: SALLE MÉC | P11: SM
A12: T. VANES SIMPLE | C12: 7 | D12: GRILLAGE 30" ET - | I12: 14 | L12: M. PRESSION | M12: MP | N12: 30" ET - | P12: HA
A13: T. VANES DOUBLE | C13: 71 | D13: GRILLAGE CADRE 31" ET + | I13: 141 | L13: H. PRESSION | M13: HP | N13: RISER | P13: RI
A14: CANEVAS 3"-3"-3" | C14: 8 | D14: STO C/A SPLIT UNITAIRE | I14: 15 | L14: 16 GA (noir) | M14: N | N14: 16GA/SS | P14: 16
A15: CANEVAS 3"-6"-3" | C15: 81 | D15: BARRES ANTI-VOL. | I15: 16 | L15: ALUMINIUM | M15: AL | N15: ALUMINIUM | P15: AL
L16: INOX | M16: SS | N16: 31" ET + | P16: RE
A18: LARG. | B18: HAUT. | C18: LONG. | D18: MÉTAL | K18: GA | L18: TÔLE | M18: ISOL. ACOUSTIQUE | O18: ISOL. THERMIQUE | Q18: DIM. AGRAN. | R18: T. VANES SIMPLE | T18: T. VANES DOUBLE | V18: CANEVAS 3-3-3 | X18: CANEVAS 3-6-3 | Z18: SPLITTERS | AA18: VCF-MANCHONS | AC18: VCFF | AE18: V. MOTORISÉ | AG18: V. MOT. ISOLÉ | AI18: V. GRAVITÉ | AK18: V. MAN. SIMPLE | AL18: V. MANUEL CADRE | AN18: GRILLAGE | AP18: GRILLAGE CADRE | AR18: BOTTINES | AS18: BARRES ANTI-VOLEUR | AU18: ALUMINIUM | AW18: TÔLE
D19: CODE | E19: TYPE | F19: INST | G19: ACCESSOIRES | L19: LBS | M19: ÉPAIS. | N19: PI.CAR. | O19: ÉPAIS. | P19: PI.CAR. | Q19: ISOLANT | R19: QTÉ | S19: PI. CAR. | T19: QTÉ | U19: PI. CAR. | V19: QTÉ | W19: PI. LIN. | X19: QTÉ | Y19: PI. LIN. | Z19: QTÉ | AA19: QTÉ | AB19: PI. LIN. | AC19: QTÉ | AD19: PI. LIN. | AE19: QTÉ | AF19: PI. CAR. | AG19: QTÉ | AH19: PI. CAR. | AI19: QTÉ | AJ19: PI. CAR. | AK19: QTÉ | AL19: QTÉ | AM19: PI. CAR. | AN19: QTÉ | AO19: PI. CAR. | AP19: QTÉ | AQ19: PI. CAR. | AR19: QTÉ | AS19: QTÉ | AT19: PI. CAR. | AU19: PI | AV19: LBS | AW19: PI | AX19: LBS
A20: 200 | B20: 200 | C20: 2 | F20: HA | G20: 21 | H20: 21 | I20: 21 | J20: 10 | K20: =IF($N$4="M",IF(A20="","",IF(D20=6,16,IF(A20<=$M$5,26,IF(A20<=$M$6,24,IF(A20<=$M$7,22,IF(A20<=$M$8,20,18)))))),IF(A20="","",IF(D20=6,16,IF(A20<=$P$5,26,IF(A20<=$P$6,24,IF(A20<=$P$7,22,IF(A20<=$P$8,20,18))))))) | L20: =IF($N$4="M",IF(A20="","",IF(K20=26,(A20+B20+Q20)*C20*0.02739,IF(K20=24,(A20+B20+Q20)*C20*0.02739,IF(K20=22,(A20+B20+Q20)*C20*0.0333,IF(K20=20,(A20+B20+Q20)*C20*0.0393,IF(K20=18,(A20+B20+Q20)*C20*0.0511,IF(K20=16,(A20+B20+Q20)*C20*0.0628))))))),IF(A20="","",IF(K20=26,(A20+B20+Q20)*C20*0.211,IF(K20=24,(A20+B20+Q20)*C20*0.211,IF(K20=22,(A20+B20+Q20)*C20*0.258,IF(K20=20,(A20+B20+Q20)*C20*0.304,IF(K20=18,(A20+B20+Q20)*C20*0.395,IF(K20=16,(A20+B20+Q20)*C20*0.487)))))))) | M20: =IF(D20=1,0.5,IF(D20=2,"1 F",IF(D20=21,"1 R",IF(D20=3,2,"")))) | N20: =IF(M20="","",IF($N$4="M",(A20+B20+Q20)*C20*0.022,(A20+B20+Q20)*C20*0.17)) | O20: =IF(D20=4,1,IF(D20=5,2,"")) | P20: =IF(O20="","",IF($N$4="M",IF(O20=1,(A20+B20+Q20)*C20*0.022*1.1,(A20+B20+Q20)*C20*0.022*1.15),IF(O20=1,(A20+B20+Q20)*C20*0.17*1.1,(A20+B20+Q20)*C20*0.17*1.15))) | Q20: =IF($N$4="M",IF(A20="","",IF(D20=1,50,IF(D20=2,100,IF(D20=21,100,IF(D20=3,200,0))))),IF(A20="","",IF(D20=1,2,IF(D20=2,4,IF(D20=21,4,IF(D20=3,8,0)))))) | R20: =COUNTIF(G20:J20,7) -> 0 | S20: =IF(A20="","",IF($N$4="M",A20*B20*0.000011111*R20*1.5,A20*B20/144*R20*1.5)) | T20: =COUNTIF(G20:J20,71) -> 0 | U20: =IF(A20="","",IF($N$4="M",A20*B20*0.000011111*T20*1.5,A20*B20/144*T20*1.5)) | V20: =COUNTIF(G20:J20,8) -> 0 | W20: =IF(A20="","",IF($N$4="M",(A20+B20)*2*0.0032808*V20,(A20+B20)*2*V20/12)) | X20: =COUNTIF(G20:J20,81) -> 0 | Y20: =IF(A20="","",IF($N$4="M",(A20+B20)*2*0.0032808*X20,(A20+B20)*2*X20/12)) | Z20: =COUNTIF(G20:J20,9) -> 0 | AA20: =COUNTIF(G20:J20,10) -> 0 | AB20: =IF(A20="","",IF($N$4="M",(A20+B20)*2*0.0032808*AA20,(A20+B20)*2*AA20/12)) | AC20: =COUNTIF(G20:J20,100) -> 0 | AE20: =COUNTIF(G20:J20,11) -> 0 | AF20: =IF(A20="","",IF($N$4="M",A20*B20*0.000011111*AE20,A20*B20/144*AE20)) | AG20: =COUNTIF(G20:J20,111) -> 0 | AH20: =IF(A20="","",IF($N$4="M",A20*B20*0.000011111*AG20,A20*B20/144*AG20)) | AI20: =COUNTIF(G20:J20,12) -> 0 | AJ20: =IF(A20="","",IF($N$4="M",A20*B20*0.000011111*AI20,A20*B20/144*AI20)) | AK20: =COUNTIF(G20:J20,13) -> 0 | AL20: =COUNTIF(G20:J20,131) -> 0 | AM20: =IF(A20="","",IF($N$4="M",A20*B20*0.000011111*AL20,A20*B20/144*AL20)) | AN20: =COUNTIF(G20:J20,14) -> 0 | AO20: =IF(A20="","",IF($N$4="M",A20*B20*0.000011111*AN20,A20*B20/144*AN20)) | AP20: =COUNTIF(G20:J20,141) -> 0 | AQ20: =IF(A20="","",IF($N$4="M",A20*B20*0.000011111*AP20,A20*B20/144*AP20)) | AR20: =COUNTIF(G20:J20,15) -> 0 | AS20: =COUNTIF(G20:J20,16) -> 0 | AT20: =IF(A20="","",IF($N$4="M",A20*B20*0.000011111*AS20,A20*B20/144*AS20)) | AU20: =IF(D20=61,C20,0) -> 0 | AV20: =IF(D20=61,L20,0) -> 0 | AW20: =IF(A20="","",(C20-AU20)) | AX20: =IF(A20="","",(L20-AV20))
A21: 200 | B21: 200 | C21: 0 | F21: HA | G21: 10 | H21: 14 | I21: 14 | J21: 14 | K21: =IF($N$4="M",IF(A21="","",IF(D21=6,16,IF(A21<=$M$5,26,IF(A21<=$M$6,24,IF(A21<=$M$7,22,IF(A21<=$M$8,20,18)))))),IF(A21="","",IF(D21=6,16,IF(A21<=$P$5,26,IF(A21<=$P$6,24,IF(A21<=$P$7,22,IF(A21<=$P$8,20,18))))))) | L21: =IF($N$4="M",IF(A21="","",IF(K21=26,(A21+B21+Q21)*C21*0.02739,IF(K21=24,(A21+B21+Q21)*C21*0.02739,IF(K21=22,(A21+B21+Q21)*C21*0.0333,IF(K21=20,(A21+B21+Q21)*C21*0.0393,IF(K21=18,(A21+B21+Q21)*C21*0.0511,IF(K21=16,(A21+B21+Q21)*C21*0.0628))))))),IF(A21="","",IF(K21=26,(A21+B21+Q21)*C21*0.211,IF(K21=24,(A21+B21+Q21)*C21*0.211,IF(K21=22,(A21+B21+Q21)*C21*0.258,IF(K21=20,(A21+B21+Q21)*C21*0.304,IF(K21=18,(A21+B21+Q21)*C21*0.395,IF(K21=16,(A21+B21+Q21)*C21*0.487)))))))) | M21: =IF(D21=1,0.5,IF(D21=2,"1 F",IF(D21=21,"1 R",IF(D21=3,2,"")))) | N21: =IF(M21="","",IF($N$4="M",(A21+B21+Q21)*C21*0.022,(A21+B21+Q21)*C21*0.17)) | O21: =IF(D21=4,1,IF(D21=5,2,"")) | P21: =IF(O21="","",IF($N$4="M",IF(O21=1,(A21+B21+Q21)*C21*0.022*1.1,(A21+B21+Q21)*C21*0.022*1.15),IF(O21=1,(A21+B21+Q21)*C21*0.17*1.1,(A21+B21+Q21)*C21*0.17*1.15))) | Q21: =IF($N$4="M",IF(A21="","",IF(D21=1,50,IF(D21=2,100,IF(D21=21,100,IF(D21=3,200,0))))),IF(A21="","",IF(D21=1,2,IF(D21=2,4,IF(D21=21,4,IF(D21=3,8,0)))))) | R21: =COUNTIF(G21:J21,7) -> 0 | S21: =IF(A21="","",IF($N$4="M",A21*B21*0.000011111*R21*1.5,A21*B21/144*R21*1.5)) | T21: =COUNTIF(G21:J21,71) -> 0 | U21: =IF(A21="","",IF($N$4="M",A21*B21*0.000011111*T21*1.5,A21*B21/144*T21*1.5)) | V21: =COUNTIF(G21:J21,8) -> 0 | W21: =IF(A21="","",IF($N$4="M",(A21+B21)*2*0.0032808*V21,(A21+B21)*2*V21/12)) | X21: =COUNTIF(G21:J21,81) -> 0 | Y21: =IF(A21="","",IF($N$4="M",(A21+B21)*2*0.0032808*X21,(A21+B21)*2*X21/12)) | Z21: =COUNTIF(G21:J21,9) -> 0 | AA21: =COUNTIF(G21:J21,10) -> 0 | AB21: =IF(A21="","",IF($N$4="M",(A21+B21)*2*0.0032808*AA21,(A21+B21)*2*AA21/12)) | AC21: =COUNTIF(G21:J21,100) -> 0 | AE21: =COUNTIF(G21:J21,11) -> 0 | AF21: =IF(A21="","",IF($N$4="M",A21*B21*0.000011111*AE21,A21*B21/144*AE21)) | AG21: =COUNTIF(G21:J21,111) -> 0 | AH21: =IF(A21="","",IF($N$4="M",A21*B21*0.000011111*AG21,A21*B21/144*AG21)) | AI21: =COUNTIF(G21:J21,12) -> 0 | AJ21: =IF(A21="","",IF($N$4="M",A21*B21*0.000011111*AI21,A21*B21/144*AI21)) | AK21: =COUNTIF(G21:J21,13) -> 0 | AL21: =COUNTIF(G21:J21,131) -> 0 | AM21: =IF(A21="","",IF($N$4="M",A21*B21*0.000011111*AL21,A21*B21/144*AL21)) | AN21: =COUNTIF(G21:J21,14) -> 0 | AO21: =IF(A21="","",IF($N$4="M",A21*B21*0.000011111*AN21,A21*B21/144*AN21)) | AP21: =COUNTIF(G21:J21,141) -> 0 | AQ21: =IF(A21="","",IF($N$4="M",A21*B21*0.000011111*AP21,A21*B21/144*AP21)) | AR21: =COUNTIF(G21:J21,15) -> 0 | AS21: =COUNTIF(G21:J21,16) -> 0 | AT21: =IF(A21="","",IF($N$4="M",A21*B21*0.000011111*AS21,A21*B21/144*AS21)) | AU21: =IF(D21=61,C21,0) -> 0 | AV21: =IF(D21=61,L21,0) -> 0 | AW21: =IF(A21="","",(C21-AU21)) | AX21: =IF(A21="","",(L21-AV21))
A22: 200 | B22: 200 | C22: 0 | F22: HA | G22: 14 | K22: =IF($N$4="M",IF(A22="","",IF(D22=6,16,IF(A22<=$M$5,26,IF(A22<=$M$6,24,IF(A22<=$M$7,22,IF(A22<=$M$8,20,18)))))),IF(A22="","",IF(D22=6,16,IF(A22<=$P$5,26,IF(A22<=$P$6,24,IF(A22<=$P$7,22,IF(A22<=$P$8,20,18))))))) | L22: =IF($N$4="M",IF(A22="","",IF(K22=26,(A22+B22+Q22)*C22*0.02739,IF(K22=24,(A22+B22+Q22)*C22*0.02739,IF(K22=22,(A22+B22+Q22)*C22*0.0333,IF(K22=20,(A22+B22+Q22)*C22*0.0393,IF(K22=18,(A22+B22+Q22)*C22*0.0511,IF(K22=16,(A22+B22+Q22)*C22*0.0628))))))),IF(A22="","",IF(K22=26,(A22+B22+Q22)*C22*0.211,IF(K22=24,(A22+B22+Q22)*C22*0.211,IF(K22=22,(A22+B22+Q22)*C22*0.258,IF(K22=20,(A22+B22+Q22)*C22*0.304,IF(K22=18,(A22+B22+Q22)*C22*0.395,IF(K22=16,(A22+B22+Q22)*C22*0.487)))))))) | M22: =IF(D22=1,0.5,IF(D22=2,"1 F",IF(D22=21,"1 R",IF(D22=3,2,"")))) | N22: =IF(M22="","",IF($N$4="M",(A22+B22+Q22)*C22*0.022,(A22+B22+Q22)*C22*0.17)) | O22: =IF(D22=4,1,IF(D22=5,2,"")) | P22: =IF(O22="","",IF($N$4="M",IF(O22=1,(A22+B22+Q22)*C22*0.022*1.1,(A22+B22+Q22)*C22*0.022*1.15),IF(O22=1,(A22+B22+Q22)*C22*0.17*1.1,(A22+B22+Q22)*C22*0.17*1.15))) | Q22: =IF($N$4="M",IF(A22="","",IF(D22=1,50,IF(D22=2,100,IF(D22=21,100,IF(D22=3,200,0))))),IF(A22="","",IF(D22=1,2,IF(D22=2,4,IF(D22=21,4,IF(D22=3,8,0)))))) | R22: =COUNTIF(G22:J22,7) -> 0 | S22: =IF(A22="","",IF($N$4="M",A22*B22*0.000011111*R22*1.5,A22*B22/144*R22*1.5)) | T22: =COUNTIF(G22:J22,71) -> 0 | U22: =IF(A22="","",IF($N$4="M",A22*B22*0.000011111*T22*1.5,A22*B22/144*T22*1.5)) | V22: =COUNTIF(G22:J22,8) -> 0 | W22: =IF(A22="","",IF($N$4="M",(A22+B22)*2*0.0032808*V22,(A22+B22)*2*V22/12)) | X22: =COUNTIF(G22:J22,81) -> 0 | Y22: =IF(A22="","",IF($N$4="M",(A22+B22)*2*0.0032808*X22,(A22+B22)*2*X22/12)) | Z22: =COUNTIF(G22:J22,9) -> 0 | AA22: =COUNTIF(G22:J22,10) -> 0 | AB22: =IF(A22="","",IF($N$4="M",(A22+B22)*2*0.0032808*AA22,(A22+B22)*2*AA22/12)) | AC22: =COUNTIF(G22:J22,100) -> 0 | AE22: =COUNTIF(G22:J22,11) -> 0 | AF22: =IF(A22="","",IF($N$4="M",A22*B22*0.000011111*AE22,A22*B22/144*AE22)) | AG22: =COUNTIF(G22:J22,111) -> 0 | AH22: =IF(A22="","",IF($N$4="M",A22*B22*0.000011111*AG22,A22*B22/144*AG22)) | AI22: =COUNTIF(G22:J22,12) -> 0 | AJ22: =IF(A22="","",IF($N$4="M",A22*B22*0.000011111*AI22,A22*B22/144*AI22)) | AK22: =COUNTIF(G22:J22,13) -> 0 | AL22: =COUNTIF(G22:J22,131) -> 0 | AM22: =IF(A22="","",IF($N$4="M",A22*B22*0.000011111*AL22,A22*B22/144*AL22)) | AN22: =COUNTIF(G22:J22,14) -> 0 | AO22: =IF(A22="","",IF($N$4="M",A22*B22*0.000011111*AN22,A22*B22/144*AN22)) | AP22: =COUNTIF(G22:J22,141) -> 0 | AQ22: =IF(A22="","",IF($N$4="M",A22*B22*0.000011111*AP22,A22*B22/144*AP22)) | AR22: =COUNTIF(G22:J22,15) -> 0 | AS22: =COUNTIF(G22:J22,16) -> 0 | AT22: =IF(A22="","",IF($N$4="M",A22*B22*0.000011111*AS22,A22*B22/144*AS22)) | AU22: =IF(D22=61,C22,0) -> 0 | AV22: =IF(D22=61,L22,0) -> 0 | AW22: =IF(A22="","",(C22-AU22)) | AX22: =IF(A22="","",(L22-AV22))
A23: 250 | B23: 250 | C23: 13.1 | F23: HA | G23: 21 | H23: 21 | I23: 21 | J23: 21 | K23: =IF($N$4="M",IF(A23="","",IF(D23=6,16,IF(A23<=$M$5,26,IF(A23<=$M$6,24,IF(A23<=$M$7,22,IF(A23<=$M$8,20,18)))))),IF(A23="","",IF(D23=6,16,IF(A23<=$P$5,26,IF(A23<=$P$6,24,IF(A23<=$P$7,22,IF(A23<=$P$8,20,18))))))) | L23: =IF($N$4="M",IF(A23="","",IF(K23=26,(A23+B23+Q23)*C23*0.02739,IF(K23=24,(A23+B23+Q23)*C23*0.02739,IF(K23=22,(A23+B23+Q23)*C23*0.0333,IF(K23=20,(A23+B23+Q23)*C23*0.0393,IF(K23=18,(A23+B23+Q23)*C23*0.0511,IF(K23=16,(A23+B23+Q23)*C23*0.0628))))))),IF(A23="","",IF(K23=26,(A23+B23+Q23)*C23*0.211,IF(K23=24,(A23+B23+Q23)*C23*0.211,IF(K23=22,(A23+B23+Q23)*C23*0.258,IF(K23=20,(A23+B23+Q23)*C23*0.304,IF(K23=18,(A23+B23+Q23)*C23*0.395,IF(K23=16,(A23+B23+Q23)*C23*0.487)))))))) | M23: =IF(D23=1,0.5,IF(D23=2,"1 F",IF(D23=21,"1 R",IF(D23=3,2,"")))) | N23: =IF(M23="","",IF($N$4="M",(A23+B23+Q23)*C23*0.022,(A23+B23+Q23)*C23*0.17)) | O23: =IF(D23=4,1,IF(D23=5,2,"")) | P23: =IF(O23="","",IF($N$4="M",IF(O23=1,(A23+B23+Q23)*C23*0.022*1.1,(A23+B23+Q23)*C23*0.022*1.15),IF(O23=1,(A23+B23+Q23)*C23*0.17*1.1,(A23+B23+Q23)*C23*0.17*1.15))) | Q23: =IF($N$4="M",IF(A23="","",IF(D23=1,50,IF(D23=2,100,IF(D23=21,100,IF(D23=3,200,0))))),IF(A23="","",IF(D23=1,2,IF(D23=2,4,IF(D23=21,4,IF(D23=3,8,0)))))) | R23: =COUNTIF(G23:J23,7) -> 0 | S23: =IF(A23="","",IF($N$4="M",A23*B23*0.000011111*R23*1.5,A23*B23/144*R23*1.5)) | T23: =COUNTIF(G23:J23,71) -> 0 | U23: =IF(A23="","",IF($N$4="M",A23*B23*0.000011111*T23*1.5,A23*B23/144*T23*1.5)) | V23: =COUNTIF(G23:J23,8) -> 0 | W23: =IF(A23="","",IF($N$4="M",(A23+B23)*2*0.0032808*V23,(A23+B23)*2*V23/12)) | X23: =COUNTIF(G23:J23,81) -> 0 | Y23: =IF(A23="","",IF($N$4="M",(A23+B23)*2*0.0032808*X23,(A23+B23)*2*X23/12)) | Z23: =COUNTIF(G23:J23,9) -> 0 | AA23: =COUNTIF(G23:J23,10) -> 0 | AB23: =IF(A23="","",IF($N$4="M",(A23+B23)*2*0.0032808*AA23,(A23+B23)*2*AA23/12)) | AC23: =COUNTIF(G23:J23,100) -> 0 | AE23: =COUNTIF(G23:J23,11) -> 0 | AF23: =IF(A23="","",IF($N$4="M",A23*B23*0.000011111*AE23,A23*B23/144*AE23)) | AG23: =COUNTIF(G23:J23,111) -> 0 | AH23: =IF(A23="","",IF($N$4="M",A23*B23*0.000011111*AG23,A23*B23/144*AG23)) | AI23: =COUNTIF(G23:J23,12) -> 0 | AJ23: =IF(A23="","",IF($N$4="M",A23*B23*0.000011111*AI23,A23*B23/144*AI23)) | AK23: =COUNTIF(G23:J23,13) -> 0 | AL23: =COUNTIF(G23:J23,131) -> 0 | AM23: =IF(A23="","",IF($N$4="M",A23*B23*0.000011111*AL23,A23*B23/144*AL23)) | AN23: =COUNTIF(G23:J23,14) -> 0 | AO23: =IF(A23="","",IF($N$4="M",A23*B23*0.000011111*AN23,A23*B23/144*AN23)) | AP23: =COUNTIF(G23:J23,141) -> 0 | AQ23: =IF(A23="","",IF($N$4="M",A23*B23*0.000011111*AP23,A23*B23/144*AP23)) | AR23: =COUNTIF(G23:J23,15) -> 0 | AS23: =COUNTIF(G23:J23,16) -> 0 | AT23: =IF(A23="","",IF($N$4="M",A23*B23*0.000011111*AS23,A23*B23/144*AS23)) | AU23: =IF(D23=61,C23,0) -> 0 | AV23: =IF(D23=61,L23,0) -> 0 | AW23: =IF(A23="","",(C23-AU23)) | AX23: =IF(A23="","",(L23-AV23))
A24: 250 | B24: 250 | C24: 0 | F24: HA | G24: 21 | H24: 21 | I24: 100 | K24: =IF($N$4="M",IF(A24="","",IF(D24=6,16,IF(A24<=$M$5,26,IF(A24<=$M$6,24,IF(A24<=$M$7,22,IF(A24<=$M$8,20,18)))))),IF(A24="","",IF(D24=6,16,IF(A24<=$P$5,26,IF(A24<=$P$6,24,IF(A24<=$P$7,22,IF(A24<=$P$8,20,18))))))) | L24: =IF($N$4="M",IF(A24="","",IF(K24=26,(A24+B24+Q24)*C24*0.02739,IF(K24=24,(A24+B24+Q24)*C24*0.02739,IF(K24=22,(A24+B24+Q24)*C24*0.0333,IF(K24=20,(A24+B24+Q24)*C24*0.0393,IF(K24=18,(A24+B24+Q24)*C24*0.0511,IF(K24=16,(A24+B24+Q24)*C24*0.0628))))))),IF(A24="","",IF(K24=26,(A24+B24+Q24)*C24*0.211,IF(K24=24,(A24+B24+Q24)*C24*0.211,IF(K24=22,(A24+B24+Q24)*C24*0.258,IF(K24=20,(A24+B24+Q24)*C24*0.304,IF(K24=18,(A24+B24+Q24)*C24*0.395,IF(K24=16,(A24+B24+Q24)*C24*0.487)))))))) | M24: =IF(D24=1,0.5,IF(D24=2,"1 F",IF(D24=21,"1 R",IF(D24=3,2,"")))) | N24: =IF(M24="","",IF($N$4="M",(A24+B24+Q24)*C24*0.022,(A24+B24+Q24)*C24*0.17)) | O24: =IF(D24=4,1,IF(D24=5,2,"")) | P24: =IF(O24="","",IF($N$4="M",IF(O24=1,(A24+B24+Q24)*C24*0.022*1.1,(A24+B24+Q24)*C24*0.022*1.15),IF(O24=1,(A24+B24+Q24)*C24*0.17*1.1,(A24+B24+Q24)*C24*0.17*1.15))) | Q24: =IF($N$4="M",IF(A24="","",IF(D24=1,50,IF(D24=2,100,IF(D24=21,100,IF(D24=3,200,0))))),IF(A24="","",IF(D24=1,2,IF(D24=2,4,IF(D24=21,4,IF(D24=3,8,0)))))) | R24: =COUNTIF(G24:J24,7) -> 0 | S24: =IF(A24="","",IF($N$4="M",A24*B24*0.000011111*R24*1.5,A24*B24/144*R24*1.5)) | T24: =COUNTIF(G24:J24,71) -> 0 | U24: =IF(A24="","",IF($N$4="M",A24*B24*0.000011111*T24*1.5,A24*B24/144*T24*1.5)) | V24: =COUNTIF(G24:J24,8) -> 0 | W24: =IF(A24="","",IF($N$4="M",(A24+B24)*2*0.0032808*V24,(A24+B24)*2*V24/12)) | X24: =COUNTIF(G24:J24,81) -> 0 | Y24: =IF(A24="","",IF($N$4="M",(A24+B24)*2*0.0032808*X24,(A24+B24)*2*X24/12)) | Z24: =COUNTIF(G24:J24,9) -> 0 | AA24: =COUNTIF(G24:J24,10) -> 0 | AB24: =IF(A24="","",IF($N$4="M",(A24+B24)*2*0.0032808*AA24,(A24+B24)*2*AA24/12)) | AC24: =COUNTIF(G24:J24,100) -> 0 | AE24: =COUNTIF(G24:J24,11) -> 0 | AF24: =IF(A24="","",IF($N$4="M",A24*B24*0.000011111*AE24,A24*B24/144*AE24)) | AG24: =COUNTIF(G24:J24,111) -> 0 | AH24: =IF(A24="","",IF($N$4="M",A24*B24*0.000011111*AG24,A24*B24/144*AG24)) | AI24: =COUNTIF(G24:J24,12) -> 0 | AJ24: =IF(A24="","",IF($N$4="M",A24*B24*0.000011111*AI24,A24*B24/144*AI24)) | AK24: =COUNTIF(G24:J24,13) -> 0 | AL24: =COUNTIF(G24:J24,131) -> 0 | AM24: =IF(A24="","",IF($N$4="M",A24*B24*0.000011111*AL24,A24*B24/144*AL24)) | AN24: =COUNTIF(G24:J24,14) -> 0 | AO24: =IF(A24="","",IF($N$4="M",A24*B24*0.000011111*AN24,A24*B24/144*AN24)) | AP24: =COUNTIF(G24:J24,141) -> 0 | AQ24: =IF(A24="","",IF($N$4="M",A24*B24*0.000011111*AP24,A24*B24/144*AP24)) | AR24: =COUNTIF(G24:J24,15) -> 0 | AS24: =COUNTIF(G24:J24,16) -> 0 | AT24: =IF(A24="","",IF($N$4="M",A24*B24*0.000011111*AS24,A24*B24/144*AS24)) | AU24: =IF(D24=61,C24,0) -> 0 | AV24: =IF(D24=61,L24,0) -> 0 | AW24: =IF(A24="","",(C24-AU24)) | AX24: =IF(A24="","",(L24-AV24))
A25: 300 | B25: 300 | C25: 7 | F25: HA | G25: 21 | H25: 21 | I25: 21 | J25: 21 | K25: =IF($N$4="M",IF(A25="","",IF(D25=6,16,IF(A25<=$M$5,26,IF(A25<=$M$6,24,IF(A25<=$M$7,22,IF(A25<=$M$8,20,18)))))),IF(A25="","",IF(D25=6,16,IF(A25<=$P$5,26,IF(A25<=$P$6,24,IF(A25<=$P$7,22,IF(A25<=$P$8,20,18))))))) | L25: =IF($N$4="M",IF(A25="","",IF(K25=26,(A25+B25+Q25)*C25*0.02739,IF(K25=24,(A25+B25+Q25)*C25*0.02739,IF(K25=22,(A25+B25+Q25)*C25*0.0333,IF(K25=20,(A25+B25+Q25)*C25*0.0393,IF(K25=18,(A25+B25+Q25)*C25*0.0511,IF(K25=16,(A25+B25+Q25)*C25*0.0628))))))),IF(A25="","",IF(K25=26,(A25+B25+Q25)*C25*0.211,IF(K25=24,(A25+B25+Q25)*C25*0.211,IF(K25=22,(A25+B25+Q25)*C25*0.258,IF(K25=20,(A25+B25+Q25)*C25*0.304,IF(K25=18,(A25+B25+Q25)*C25*0.395,IF(K25=16,(A25+B25+Q25)*C25*0.487)))))))) | M25: =IF(D25=1,0.5,IF(D25=2,"1 F",IF(D25=21,"1 R",IF(D25=3,2,"")))) | N25: =IF(M25="","",IF($N$4="M",(A25+B25+Q25)*C25*0.022,(A25+B25+Q25)*C25*0.17)) | O25: =IF(D25=4,1,IF(D25=5,2,"")) | P25: =IF(O25="","",IF($N$4="M",IF(O25=1,(A25+B25+Q25)*C25*0.022*1.1,(A25+B25+Q25)*C25*0.022*1.15),IF(O25=1,(A25+B25+Q25)*C25*0.17*1.1,(A25+B25+Q25)*C25*0.17*1.15))) | Q25: =IF($N$4="M",IF(A25="","",IF(D25=1,50,IF(D25=2,100,IF(D25=21,100,IF(D25=3,200,0))))),IF(A25="","",IF(D25=1,2,IF(D25=2,4,IF(D25=21,4,IF(D25=3,8,0)))))) | R25: =COUNTIF(G25:J25,7) -> 0 | S25: =IF(A25="","",IF($N$4="M",A25*B25*0.000011111*R25*1.5,A25*B25/144*R25*1.5)) | T25: =COUNTIF(G25:J25,71) -> 0 | U25: =IF(A25="","",IF($N$4="M",A25*B25*0.000011111*T25*1.5,A25*B25/144*T25*1.5)) | V25: =COUNTIF(G25:J25,8) -> 0 | W25: =IF(A25="","",IF($N$4="M",(A25+B25)*2*0.0032808*V25,(A25+B25)*2*V25/12)) | X25: =COUNTIF(G25:J25,81) -> 0 | Y25: =IF(A25="","",IF($N$4="M",(A25+B25)*2*0.0032808*X25,(A25+B25)*2*X25/12)) | Z25: =COUNTIF(G25:J25,9) -> 0 | AA25: =COUNTIF(G25:J25,10) -> 0 | AB25: =IF(A25="","",IF($N$4="M",(A25+B25)*2*0.0032808*AA25,(A25+B25)*2*AA25/12)) | AC25: =COUNTIF(G25:J25,100) -> 0 | AE25: =COUNTIF(G25:J25,11) -> 0 | AF25: =IF(A25="","",IF($N$4="M",A25*B25*0.000011111*AE25,A25*B25/144*AE25)) | AG25: =COUNTIF(G25:J25,111) -> 0 | AH25: =IF(A25="","",IF($N$4="M",A25*B25*0.000011111*AG25,A25*B25/144*AG25)) | AI25: =COUNTIF(G25:J25,12) -> 0 | AJ25: =IF(A25="","",IF($N$4="M",A25*B25*0.000011111*AI25,A25*B25/144*AI25)) | AK25: =COUNTIF(G25:J25,13) -> 0 | AL25: =COUNTIF(G25:J25,131) -> 0 | AM25: =IF(A25="","",IF($N$4="M",A25*B25*0.000011111*AL25,A25*B25/144*AL25)) | AN25: =COUNTIF(G25:J25,14) -> 0 | AO25: =IF(A25="","",IF($N$4="M",A25*B25*0.000011111*AN25,A25*B25/144*AN25)) | AP25: =COUNTIF(G25:J25,141) -> 0 | AQ25: =IF(A25="","",IF($N$4="M",A25*B25*0.000011111*AP25,A25*B25/144*AP25)) | AR25: =COUNTIF(G25:J25,15) -> 0 | AS25: =COUNTIF(G25:J25,16) -> 0 | AT25: =IF(A25="","",IF($N$4="M",A25*B25*0.000011111*AS25,A25*B25/144*AS25)) | AU25: =IF(D25=61,C25,0) -> 0 | AV25: =IF(D25=61,L25,0) -> 0 | AW25: =IF(A25="","",(C25-AU25)) | AX25: =IF(A25="","",(L25-AV25))
A26: 1000 | B26: 400 | C26: 14.9 | F26: RE | K26: =IF($N$4="M",IF(A26="","",IF(D26=6,16,IF(A26<=$M$5,26,IF(A26<=$M$6,24,IF(A26<=$M$7,22,IF(A26<=$M$8,20,18)))))),IF(A26="","",IF(D26=6,16,IF(A26<=$P$5,26,IF(A26<=$P$6,24,IF(A26<=$P$7,22,IF(A26<=$P$8,20,18))))))) | L26: =IF($N$4="M",IF(A26="","",IF(K26=26,(A26+B26+Q26)*C26*0.02739,IF(K26=24,(A26+B26+Q26)*C26*0.02739,IF(K26=22,(A26+B26+Q26)*C26*0.0333,IF(K26=20,(A26+B26+Q26)*C26*0.0393,IF(K26=18,(A26+B26+Q26)*C26*0.0511,IF(K26=16,(A26+B26+Q26)*C26*0.0628))))))),IF(A26="","",IF(K26=26,(A26+B26+Q26)*C26*0.211,IF(K26=24,(A26+B26+Q26)*C26*0.211,IF(K26=22,(A26+B26+Q26)*C26*0.258,IF(K26=20,(A26+B26+Q26)*C26*0.304,IF(K26=18,(A26+B26+Q26)*C26*0.395,IF(K26=16,(A26+B26+Q26)*C26*0.487)))))))) | M26: =IF(D26=1,0.5,IF(D26=2,"1 F",IF(D26=21,"1 R",IF(D26=3,2,"")))) | N26: =IF(M26="","",IF($N$4="M",(A26+B26+Q26)*C26*0.022,(A26+B26+Q26)*C26*0.17)) | O26: =IF(D26=4,1,IF(D26=5,2,"")) | P26: =IF(O26="","",IF($N$4="M",IF(O26=1,(A26+B26+Q26)*C26*0.022*1.1,(A26+B26+Q26)*C26*0.022*1.15),IF(O26=1,(A26+B26+Q26)*C26*0.17*1.1,(A26+B26+Q26)*C26*0.17*1.15))) | Q26: =IF($N$4="M",IF(A26="","",IF(D26=1,50,IF(D26=2,100,IF(D26=21,100,IF(D26=3,200,0))))),IF(A26="","",IF(D26=1,2,IF(D26=2,4,IF(D26=21,4,IF(D26=3,8,0)))))) | R26: =COUNTIF(G26:J26,7) -> 0 | S26: =IF(A26="","",IF($N$4="M",A26*B26*0.000011111*R26*1.5,A26*B26/144*R26*1.5)) | T26: =COUNTIF(G26:J26,71) -> 0 | U26: =IF(A26="","",IF($N$4="M",A26*B26*0.000011111*T26*1.5,A26*B26/144*T26*1.5)) | V26: =COUNTIF(G26:J26,8) -> 0 | W26: =IF(A26="","",IF($N$4="M",(A26+B26)*2*0.0032808*V26,(A26+B26)*2*V26/12)) | X26: =COUNTIF(G26:J26,81) -> 0 | Y26: =IF(A26="","",IF($N$4="M",(A26+B26)*2*0.0032808*X26,(A26+B26)*2*X26/12)) | Z26: =COUNTIF(G26:J26,9) -> 0 | AA26: =COUNTIF(G26:J26,10) -> 0 | AB26: =IF(A26="","",IF($N$4="M",(A26+B26)*2*0.0032808*AA26,(A26+B26)*2*AA26/12)) | AC26: =COUNTIF(G26:J26,100) -> 0 | AE26: =COUNTIF(G26:J26,11) -> 0 | AF26: =IF(A26="","",IF($N$4="M",A26*B26*0.000011111*AE26,A26*B26/144*AE26)) | AG26: =COUNTIF(G26:J26,111) -> 0 | AH26: =IF(A26="","",IF($N$4="M",A26*B26*0.000011111*AG26,A26*B26/144*AG26)) | AI26: =COUNTIF(G26:J26,12) -> 0 | AJ26: =IF(A26="","",IF($N$4="M",A26*B26*0.000011111*AI26,A26*B26/144*AI26)) | AK26: =COUNTIF(G26:J26,13) -> 0 | AL26: =COUNTIF(G26:J26,131) -> 0 | AM26: =IF(A26="","",IF($N$4="M",A26*B26*0.000011111*AL26,A26*B26/144*AL26)) | AN26: =COUNTIF(G26:J26,14) -> 0 | AO26: =IF(A26="","",IF($N$4="M",A26*B26*0.000011111*AN26,A26*B26/144*AN26)) | AP26: =COUNTIF(G26:J26,141) -> 0 | AQ26: =IF(A26="","",IF($N$4="M",A26*B26*0.000011111*AP26,A26*B26/144*AP26)) | AR26: =COUNTIF(G26:J26,15) -> 0 | AS26: =COUNTIF(G26:J26,16) -> 0 | AT26: =IF(A26="","",IF($N$4="M",A26*B26*0.000011111*AS26,A26*B26/144*AS26)) | AU26: =IF(D26=61,C26,0) -> 0 | AV26: =IF(D26=61,L26,0) -> 0 | AW26: =IF(A26="","",(C26-AU26)) | AX26: =IF(A26="","",(L26-AV26))
A27: 1000 | B27: 500 | C27: 17.3 | F27: RE | K27: =IF($N$4="M",IF(A27="","",IF(D27=6,16,IF(A27<=$M$5,26,IF(A27<=$M$6,24,IF(A27<=$M$7,22,IF(A27<=$M$8,20,18)))))),IF(A27="","",IF(D27=6,16,IF(A27<=$P$5,26,IF(A27<=$P$6,24,IF(A27<=$P$7,22,IF(A27<=$P$8,20,18))))))) | L27: =IF($N$4="M",IF(A27="","",IF(K27=26,(A27+B27+Q27)*C27*0.02739,IF(K27=24,(A27+B27+Q27)*C27*0.02739,IF(K27=22,(A27+B27+Q27)*C27*0.0333,IF(K27=20,(A27+B27+Q27)*C27*0.0393,IF(K27=18,(A27+B27+Q27)*C27*0.0511,IF(K27=16,(A27+B27+Q27)*C27*0.0628))))))),IF(A27="","",IF(K27=26,(A27+B27+Q27)*C27*0.211,IF(K27=24,(A27+B27+Q27)*C27*0.211,IF(K27=22,(A27+B27+Q27)*C27*0.258,IF(K27=20,(A27+B27+Q27)*C27*0.304,IF(K27=18,(A27+B27+Q27)*C27*0.395,IF(K27=16,(A27+B27+Q27)*C27*0.487)))))))) | M27: =IF(D27=1,0.5,IF(D27=2,"1 F",IF(D27=21,"1 R",IF(D27=3,2,"")))) | N27: =IF(M27="","",IF($N$4="M",(A27+B27+Q27)*C27*0.022,(A27+B27+Q27)*C27*0.17)) | O27: =IF(D27=4,1,IF(D27=5,2,"")) | P27: =IF(O27="","",IF($N$4="M",IF(O27=1,(A27+B27+Q27)*C27*0.022*1.1,(A27+B27+Q27)*C27*0.022*1.15),IF(O27=1,(A27+B27+Q27)*C27*0.17*1.1,(A27+B27+Q27)*C27*0.17*1.15))) | Q27: =IF($N$4="M",IF(A27="","",IF(D27=1,50,IF(D27=2,100,IF(D27=21,100,IF(D27=3,200,0))))),IF(A27="","",IF(D27=1,2,IF(D27=2,4,IF(D27=21,4,IF(D27=3,8,0)))))) | R27: =COUNTIF(G27:J27,7) -> 0 | S27: =IF(A27="","",IF($N$4="M",A27*B27*0.000011111*R27*1.5,A27*B27/144*R27*1.5)) | T27: =COUNTIF(G27:J27,71) -> 0 | U27: =IF(A27="","",IF($N$4="M",A27*B27*0.000011111*T27*1.5,A27*B27/144*T27*1.5)) | V27: =COUNTIF(G27:J27,8) -> 0 | W27: =IF(A27="","",IF($N$4="M",(A27+B27)*2*0.0032808*V27,(A27+B27)*2*V27/12)) | X27: =COUNTIF(G27:J27,81) -> 0 | Y27: =IF(A27="","",IF($N$4="M",(A27+B27)*2*0.0032808*X27,(A27+B27)*2*X27/12)) | Z27: =COUNTIF(G27:J27,9) -> 0 | AA27: =COUNTIF(G27:J27,10) -> 0 | AB27: =IF(A27="","",IF($N$4="M",(A27+B27)*2*0.0032808*AA27,(A27+B27)*2*AA27/12)) | AC27: =COUNTIF(G27:J27,100) -> 0 | AE27: =COUNTIF(G27:J27,11) -> 0 | AF27: =IF(A27="","",IF($N$4="M",A27*B27*0.000011111*AE27,A27*B27/144*AE27)) | AG27: =COUNTIF(G27:J27,111) -> 0 | AH27: =IF(A27="","",IF($N$4="M",A27*B27*0.000011111*AG27,A27*B27/144*AG27)) | AI27: =COUNTIF(G27:J27,12) -> 0 | AJ27: =IF(A27="","",IF($N$4="M",A27*B27*0.000011111*AI27,A27*B27/144*AI27)) | AK27: =COUNTIF(G27:J27,13) -> 0 | AL27: =COUNTIF(G27:J27,131) -> 0 | AM27: =IF(A27="","",IF($N$4="M",A27*B27*0.000011111*AL27,A27*B27/144*AL27)) | AN27: =COUNTIF(G27:J27,14) -> 0 | AO27: =IF(A27="","",IF($N$4="M",A27*B27*0.000011111*AN27,A27*B27/144*AN27)) | AP27: =COUNTIF(G27:J27,141) -> 0 | AQ27: =IF(A27="","",IF($N$4="M",A27*B27*0.000011111*AP27,A27*B27/144*AP27)) | AR27: =COUNTIF(G27:J27,15) -> 0 | AS27: =COUNTIF(G27:J27,16) -> 0 | AT27: =IF(A27="","",IF($N$4="M",A27*B27*0.000011111*AS27,A27*B27/144*AS27)) | AU27: =IF(D27=61,C27,0) -> 0 | AV27: =IF(D27=61,L27,0) -> 0 | AW27: =IF(A27="","",(C27-AU27)) | AX27: =IF(A27="","",(L27-AV27))
A28: 1000 | B28: 500 | C28: 4.3 | D28: 6 | E28: HP | F28: RE | G28: 21 | K28: =IF($N$4="M",IF(A28="","",IF(D28=6,16,IF(A28<=$M$5,26,IF(A28<=$M$6,24,IF(A28<=$M$7,22,IF(A28<=$M$8,20,18)))))),IF(A28="","",IF(D28=6,16,IF(A28<=$P$5,26,IF(A28<=$P$6,24,IF(A28<=$P$7,22,IF(A28<=$P$8,20,18))))))) | L28: =IF($N$4="M",IF(A28="","",IF(K28=26,(A28+B28+Q28)*C28*0.02739,IF(K28=24,(A28+B28+Q28)*C28*0.02739,IF(K28=22,(A28+B28+Q28)*C28*0.0333,IF(K28=20,(A28+B28+Q28)*C28*0.0393,IF(K28=18,(A28+B28+Q28)*C28*0.0511,IF(K28=16,(A28+B28+Q28)*C28*0.0628))))))),IF(A28="","",IF(K28=26,(A28+B28+Q28)*C28*0.211,IF(K28=24,(A28+B28+Q28)*C28*0.211,IF(K28=22,(A28+B28+Q28)*C28*0.258,IF(K28=20,(A28+B28+Q28)*C28*0.304,IF(K28=18,(A28+B28+Q28)*C28*0.395,IF(K28=16,(A28+B28+Q28)*C28*0.487)))))))) | M28: =IF(D28=1,0.5,IF(D28=2,"1 F",IF(D28=21,"1 R",IF(D28=3,2,"")))) | N28: =IF(M28="","",IF($N$4="M",(A28+B28+Q28)*C28*0.022,(A28+B28+Q28)*C28*0.17)) | O28: =IF(D28=4,1,IF(D28=5,2,"")) | P28: =IF(O28="","",IF($N$4="M",IF(O28=1,(A28+B28+Q28)*C28*0.022*1.1,(A28+B28+Q28)*C28*0.022*1.15),IF(O28=1,(A28+B28+Q28)*C28*0.17*1.1,(A28+B28+Q28)*C28*0.17*1.15))) | Q28: =IF($N$4="M",IF(A28="","",IF(D28=1,50,IF(D28=2,100,IF(D28=21,100,IF(D28=3,200,0))))),IF(A28="","",IF(D28=1,2,IF(D28=2,4,IF(D28=21,4,IF(D28=3,8,0)))))) | R28: =COUNTIF(G28:J28,7) -> 0 | S28: =IF(A28="","",IF($N$4="M",A28*B28*0.000011111*R28*1.5,A28*B28/144*R28*1.5)) | T28: =COUNTIF(G28:J28,71) -> 0 | U28: =IF(A28="","",IF($N$4="M",A28*B28*0.000011111*T28*1.5,A28*B28/144*T28*1.5)) | V28: =COUNTIF(G28:J28,8) -> 0 | W28: =IF(A28="","",IF($N$4="M",(A28+B28)*2*0.0032808*V28,(A28+B28)*2*V28/12)) | X28: =COUNTIF(G28:J28,81) -> 0 | Y28: =IF(A28="","",IF($N$4="M",(A28+B28)*2*0.0032808*X28,(A28+B28)*2*X28/12)) | Z28: =COUNTIF(G28:J28,9) -> 0 | AA28: =COUNTIF(G28:J28,10) -> 0 | AB28: =IF(A28="","",IF($N$4="M",(A28+B28)*2*0.0032808*AA28,(A28+B28)*2*AA28/12)) | AC28: =COUNTIF(G28:J28,100) -> 0 | AE28: =COUNTIF(G28:J28,11) -> 0 | AF28: =IF(A28="","",IF($N$4="M",A28*B28*0.000011111*AE28,A28*B28/144*AE28)) | AG28: =COUNTIF(G28:J28,111) -> 0 | AH28: =IF(A28="","",IF($N$4="M",A28*B28*0.000011111*AG28,A28*B28/144*AG28)) | AI28: =COUNTIF(G28:J28,12) -> 0 | AJ28: =IF(A28="","",IF($N$4="M",A28*B28*0.000011111*AI28,A28*B28/144*AI28)) | AK28: =COUNTIF(G28:J28,13) -> 0 | AL28: =COUNTIF(G28:J28,131) -> 0 | AM28: =IF(A28="","",IF($N$4="M",A28*B28*0.000011111*AL28,A28*B28/144*AL28)) | AN28: =COUNTIF(G28:J28,14) -> 0 | AO28: =IF(A28="","",IF($N$4="M",A28*B28*0.000011111*AN28,A28*B28/144*AN28)) | AP28: =COUNTIF(G28:J28,141) -> 0 | AQ28: =IF(A28="","",IF($N$4="M",A28*B28*0.000011111*AP28,A28*B28/144*AP28)) | AR28: =COUNTIF(G28:J28,15) -> 0 | AS28: =COUNTIF(G28:J28,16) -> 0 | AT28: =IF(A28="","",IF($N$4="M",A28*B28*0.000011111*AS28,A28*B28/144*AS28)) | AU28: =IF(D28=61,C28,0) -> 0 | AV28: =IF(D28=61,L28,0) -> 0 | AW28: =IF(A28="","",(C28-AU28)) | AX28: =IF(A28="","",(L28-AV28))
A29: 1000 | B29: 600 | C29: 6.8 | D29: 6 | E29: HP | F29: RE | K29: =IF($N$4="M",IF(A29="","",IF(D29=6,16,IF(A29<=$M$5,26,IF(A29<=$M$6,24,IF(A29<=$M$7,22,IF(A29<=$M$8,20,18)))))),IF(A29="","",IF(D29=6,16,IF(A29<=$P$5,26,IF(A29<=$P$6,24,IF(A29<=$P$7,22,IF(A29<=$P$8,20,18))))))) | L29: =IF($N$4="M",IF(A29="","",IF(K29=26,(A29+B29+Q29)*C29*0.02739,IF(K29=24,(A29+B29+Q29)*C29*0.02739,IF(K29=22,(A29+B29+Q29)*C29*0.0333,IF(K29=20,(A29+B29+Q29)*C29*0.0393,IF(K29=18,(A29+B29+Q29)*C29*0.0511,IF(K29=16,(A29+B29+Q29)*C29*0.0628))))))),IF(A29="","",IF(K29=26,(A29+B29+Q29)*C29*0.211,IF(K29=24,(A29+B29+Q29)*C29*0.211,IF(K29=22,(A29+B29+Q29)*C29*0.258,IF(K29=20,(A29+B29+Q29)*C29*0.304,IF(K29=18,(A29+B29+Q29)*C29*0.395,IF(K29=16,(A29+B29+Q29)*C29*0.487)))))))) | M29: =IF(D29=1,0.5,IF(D29=2,"1 F",IF(D29=21,"1 R",IF(D29=3,2,"")))) | N29: =IF(M29="","",IF($N$4="M",(A29+B29+Q29)*C29*0.022,(A29+B29+Q29)*C29*0.17)) | O29: =IF(D29=4,1,IF(D29=5,2,"")) | P29: =IF(O29="","",IF($N$4="M",IF(O29=1,(A29+B29+Q29)*C29*0.022*1.1,(A29+B29+Q29)*C29*0.022*1.15),IF(O29=1,(A29+B29+Q29)*C29*0.17*1.1,(A29+B29+Q29)*C29*0.17*1.15))) | Q29: =IF($N$4="M",IF(A29="","",IF(D29=1,50,IF(D29=2,100,IF(D29=21,100,IF(D29=3,200,0))))),IF(A29="","",IF(D29=1,2,IF(D29=2,4,IF(D29=21,4,IF(D29=3,8,0)))))) | R29: =COUNTIF(G29:J29,7) -> 0 | S29: =IF(A29="","",IF($N$4="M",A29*B29*0.000011111*R29*1.5,A29*B29/144*R29*1.5)) | T29: =COUNTIF(G29:J29,71) -> 0 | U29: =IF(A29="","",IF($N$4="M",A29*B29*0.000011111*T29*1.5,A29*B29/144*T29*1.5)) | V29: =COUNTIF(G29:J29,8) -> 0 | W29: =IF(A29="","",IF($N$4="M",(A29+B29)*2*0.0032808*V29,(A29+B29)*2*V29/12)) | X29: =COUNTIF(G29:J29,81) -> 0 | Y29: =IF(A29="","",IF($N$4="M",(A29+B29)*2*0.0032808*X29,(A29+B29)*2*X29/12)) | Z29: =COUNTIF(G29:J29,9) -> 0 | AA29: =COUNTIF(G29:J29,10) -> 0 | AB29: =IF(A29="","",IF($N$4="M",(A29+B29)*2*0.0032808*AA29,(A29+B29)*2*AA29/12)) | AC29: =COUNTIF(G29:J29,100) -> 0 | AE29: =COUNTIF(G29:J29,11) -> 0 | AF29: =IF(A29="","",IF($N$4="M",A29*B29*0.000011111*AE29,A29*B29/144*AE29)) | AG29: =COUNTIF(G29:J29,111) -> 0 | AH29: =IF(A29="","",IF($N$4="M",A29*B29*0.000011111*AG29,A29*B29/144*AG29)) | AI29: =COUNTIF(G29:J29,12) -> 0 | AJ29: =IF(A29="","",IF($N$4="M",A29*B29*0.000011111*AI29,A29*B29/144*AI29)) | AK29: =COUNTIF(G29:J29,13) -> 0 | AL29: =COUNTIF(G29:J29,131) -> 0 | AM29: =IF(A29="","",IF($N$4="M",A29*B29*0.000011111*AL29,A29*B29/144*AL29)) | AN29: =COUNTIF(G29:J29,14) -> 0 | AO29: =IF(A29="","",IF($N$4="M",A29*B29*0.000011111*AN29,A29*B29/144*AN29)) | AP29: =COUNTIF(G29:J29,141) -> 0 | AQ29: =IF(A29="","",IF($N$4="M",A29*B29*0.000011111*AP29,A29*B29/144*AP29)) | AR29: =COUNTIF(G29:J29,15) -> 0 | AS29: =COUNTIF(G29:J29,16) -> 0 | AT29: =IF(A29="","",IF($N$4="M",A29*B29*0.000011111*AS29,A29*B29/144*AS29)) | AU29: =IF(D29=61,C29,0) -> 0 | AV29: =IF(D29=61,L29,0) -> 0 | AW29: =IF(A29="","",(C29-AU29)) | AX29: =IF(A29="","",(L29-AV29))
A30: 1200 | B30: 400 | C30: 14.9 | F30: RE | G30: 71 | H30: 10 | I30: 10 | K30: =IF($N$4="M",IF(A30="","",IF(D30=6,16,IF(A30<=$M$5,26,IF(A30<=$M$6,24,IF(A30<=$M$7,22,IF(A30<=$M$8,20,18)))))),IF(A30="","",IF(D30=6,16,IF(A30<=$P$5,26,IF(A30<=$P$6,24,IF(A30<=$P$7,22,IF(A30<=$P$8,20,18))))))) | L30: =IF($N$4="M",IF(A30="","",IF(K30=26,(A30+B30+Q30)*C30*0.02739,IF(K30=24,(A30+B30+Q30)*C30*0.02739,IF(K30=22,(A30+B30+Q30)*C30*0.0333,IF(K30=20,(A30+B30+Q30)*C30*0.0393,IF(K30=18,(A30+B30+Q30)*C30*0.0511,IF(K30=16,(A30+B30+Q30)*C30*0.0628))))))),IF(A30="","",IF(K30=26,(A30+B30+Q30)*C30*0.211,IF(K30=24,(A30+B30+Q30)*C30*0.211,IF(K30=22,(A30+B30+Q30)*C30*0.258,IF(K30=20,(A30+B30+Q30)*C30*0.304,IF(K30=18,(A30+B30+Q30)*C30*0.395,IF(K30=16,(A30+B30+Q30)*C30*0.487)))))))) | M30: =IF(D30=1,0.5,IF(D30=2,"1 F",IF(D30=21,"1 R",IF(D30=3,2,"")))) | N30: =IF(M30="","",IF($N$4="M",(A30+B30+Q30)*C30*0.022,(A30+B30+Q30)*C30*0.17)) | O30: =IF(D30=4,1,IF(D30=5,2,"")) | P30: =IF(O30="","",IF($N$4="M",IF(O30=1,(A30+B30+Q30)*C30*0.022*1.1,(A30+B30+Q30)*C30*0.022*1.15),IF(O30=1,(A30+B30+Q30)*C30*0.17*1.1,(A30+B30+Q30)*C30*0.17*1.15))) | Q30: =IF($N$4="M",IF(A30="","",IF(D30=1,50,IF(D30=2,100,IF(D30=21,100,IF(D30=3,200,0))))),IF(A30="","",IF(D30=1,2,IF(D30=2,4,IF(D30=21,4,IF(D30=3,8,0)))))) | R30: =COUNTIF(G30:J30,7) -> 0 | S30: =IF(A30="","",IF($N$4="M",A30*B30*0.000011111*R30*1.5,A30*B30/144*R30*1.5)) | T30: =COUNTIF(G30:J30,71) -> 0 | U30: =IF(A30="","",IF($N$4="M",A30*B30*0.000011111*T30*1.5,A30*B30/144*T30*1.5)) | V30: =COUNTIF(G30:J30,8) -> 0 | W30: =IF(A30="","",IF($N$4="M",(A30+B30)*2*0.0032808*V30,(A30+B30)*2*V30/12)) | X30: =COUNTIF(G30:J30,81) -> 0 | Y30: =IF(A30="","",IF($N$4="M",(A30+B30)*2*0.0032808*X30,(A30+B30)*2*X30/12)) | Z30: =COUNTIF(G30:J30,9) -> 0 | AA30: =COUNTIF(G30:J30,10) -> 0 | AB30: =IF(A30="","",IF($N$4="M",(A30+B30)*2*0.0032808*AA30,(A30+B30)*2*AA30/12)) | AC30: =COUNTIF(G30:J30,100) -> 0 | AE30: =COUNTIF(G30:J30,11) -> 0 | AF30: =IF(A30="","",IF($N$4="M",A30*B30*0.000011111*AE30,A30*B30/144*AE30)) | AG30: =COUNTIF(G30:J30,111) -> 0 | AH30: =IF(A30="","",IF($N$4="M",A30*B30*0.000011111*AG30,A30*B30/144*AG30)) | AI30: =COUNTIF(G30:J30,12) -> 0 | AJ30: =IF(A30="","",IF($N$4="M",A30*B30*0.000011111*AI30,A30*B30/144*AI30)) | AK30: =COUNTIF(G30:J30,13) -> 0 | AL30: =COUNTIF(G30:J30,131) -> 0 | AM30: =IF(A30="","",IF($N$4="M",A30*B30*0.000011111*AL30,A30*B30/144*AL30)) | AN30: =COUNTIF(G30:J30,14) -> 0 | AO30: =IF(A30="","",IF($N$4="M",A30*B30*0.000011111*AN30,A30*B30/144*AN30)) | AP30: =COUNTIF(G30:J30,141) -> 0 | AQ30: =IF(A30="","",IF($N$4="M",A30*B30*0.000011111*AP30,A30*B30/144*AP30)) | AR30: =COUNTIF(G30:J30,15) -> 0 | AS30: =COUNTIF(G30:J30,16) -> 0 | AT30: =IF(A30="","",IF($N$4="M",A30*B30*0.000011111*AS30,A30*B30/144*AS30)) | AU30: =IF(D30=61,C30,0) -> 0 | AV30: =IF(D30=61,L30,0) -> 0 | AW30: =IF(A30="","",(C30-AU30)) | AX30: =IF(A30="","",(L30-AV30))
A31: 1200 | B31: 600 | C31: 8 | D31: 6 | E31: HP | F31: RE | G31: 21 | H31: 81 | K31: =IF($N$4="M",IF(A31="","",IF(D31=6,16,IF(A31<=$M$5,26,IF(A31<=$M$6,24,IF(A31<=$M$7,22,IF(A31<=$M$8,20,18)))))),IF(A31="","",IF(D31=6,16,IF(A31<=$P$5,26,IF(A31<=$P$6,24,IF(A31<=$P$7,22,IF(A31<=$P$8,20,18))))))) | L31: =IF($N$4="M",IF(A31="","",IF(K31=26,(A31+B31+Q31)*C31*0.02739,IF(K31=24,(A31+B31+Q31)*C31*0.02739,IF(K31=22,(A31+B31+Q31)*C31*0.0333,IF(K31=20,(A31+B31+Q31)*C31*0.0393,IF(K31=18,(A31+B31+Q31)*C31*0.0511,IF(K31=16,(A31+B31+Q31)*C31*0.0628))))))),IF(A31="","",IF(K31=26,(A31+B31+Q31)*C31*0.211,IF(K31=24,(A31+B31+Q31)*C31*0.211,IF(K31=22,(A31+B31+Q31)*C31*0.258,IF(K31=20,(A31+B31+Q31)*C31*0.304,IF(K31=18,(A31+B31+Q31)*C31*0.395,IF(K31=16,(A31+B31+Q31)*C31*0.487)))))))) | M31: =IF(D31=1,0.5,IF(D31=2,"1 F",IF(D31=21,"1 R",IF(D31=3,2,"")))) | N31: =IF(M31="","",IF($N$4="M",(A31+B31+Q31)*C31*0.022,(A31+B31+Q31)*C31*0.17)) | O31: =IF(D31=4,1,IF(D31=5,2,"")) | P31: =IF(O31="","",IF($N$4="M",IF(O31=1,(A31+B31+Q31)*C31*0.022*1.1,(A31+B31+Q31)*C31*0.022*1.15),IF(O31=1,(A31+B31+Q31)*C31*0.17*1.1,(A31+B31+Q31)*C31*0.17*1.15))) | Q31: =IF($N$4="M",IF(A31="","",IF(D31=1,50,IF(D31=2,100,IF(D31=21,100,IF(D31=3,200,0))))),IF(A31="","",IF(D31=1,2,IF(D31=2,4,IF(D31=21,4,IF(D31=3,8,0)))))) | R31: =COUNTIF(G31:J31,7) -> 0 | S31: =IF(A31="","",IF($N$4="M",A31*B31*0.000011111*R31*1.5,A31*B31/144*R31*1.5)) | T31: =COUNTIF(G31:J31,71) -> 0 | U31: =IF(A31="","",IF($N$4="M",A31*B31*0.000011111*T31*1.5,A31*B31/144*T31*1.5)) | V31: =COUNTIF(G31:J31,8) -> 0 | W31: =IF(A31="","",IF($N$4="M",(A31+B31)*2*0.0032808*V31,(A31+B31)*2*V31/12)) | X31: =COUNTIF(G31:J31,81) -> 0 | Y31: =IF(A31="","",IF($N$4="M",(A31+B31)*2*0.0032808*X31,(A31+B31)*2*X31/12)) | Z31: =COUNTIF(G31:J31,9) -> 0 | AA31: =COUNTIF(G31:J31,10) -> 0 | AB31: =IF(A31="","",IF($N$4="M",(A31+B31)*2*0.0032808*AA31,(A31+B31)*2*AA31/12)) | AC31: =COUNTIF(G31:J31,100) -> 0 | AE31: =COUNTIF(G31:J31,11) -> 0 | AF31: =IF(A31="","",IF($N$4="M",A31*B31*0.000011111*AE31,A31*B31/144*AE31)) | AG31: =COUNTIF(G31:J31,111) -> 0 | AH31: =IF(A31="","",IF($N$4="M",A31*B31*0.000011111*AG31,A31*B31/144*AG31)) | AI31: =COUNTIF(G31:J31,12) -> 0 | AJ31: =IF(A31="","",IF($N$4="M",A31*B31*0.000011111*AI31,A31*B31/144*AI31)) | AK31: =COUNTIF(G31:J31,13) -> 0 | AL31: =COUNTIF(G31:J31,131) -> 0 | AM31: =IF(A31="","",IF($N$4="M",A31*B31*0.000011111*AL31,A31*B31/144*AL31)) | AN31: =COUNTIF(G31:J31,14) -> 0 | AO31: =IF(A31="","",IF($N$4="M",A31*B31*0.000011111*AN31,A31*B31/144*AN31)) | AP31: =COUNTIF(G31:J31,141) -> 0 | AQ31: =IF(A31="","",IF($N$4="M",A31*B31*0.000011111*AP31,A31*B31/144*AP31)) | AR31: =COUNTIF(G31:J31,15) -> 0 | AS31: =COUNTIF(G31:J31,16) -> 0 | AT31: =IF(A31="","",IF($N$4="M",A31*B31*0.000011111*AS31,A31*B31/144*AS31)) | AU31: =IF(D31=61,C31,0) -> 0 | AV31: =IF(D31=61,L31,0) -> 0 | AW31: =IF(A31="","",(C31-AU31)) | AX31: =IF(A31="","",(L31-AV31))
A32: 150 | B32: 150 | C32: 80.5 | F32: HA | G32: 100 | H32: 7 | I32: 13 | J32: 13 | K32: =IF($N$4="M",IF(A32="","",IF(D32=6,16,IF(A32<=$M$5,26,IF(A32<=$M$6,24,IF(A32<=$M$7,22,IF(A32<=$M$8,20,18)))))),IF(A32="","",IF(D32=6,16,IF(A32<=$P$5,26,IF(A32<=$P$6,24,IF(A32<=$P$7,22,IF(A32<=$P$8,20,18))))))) | L32: =IF($N$4="M",IF(A32="","",IF(K32=26,(A32+B32+Q32)*C32*0.02739,IF(K32=24,(A32+B32+Q32)*C32*0.02739,IF(K32=22,(A32+B32+Q32)*C32*0.0333,IF(K32=20,(A32+B32+Q32)*C32*0.0393,IF(K32=18,(A32+B32+Q32)*C32*0.0511,IF(K32=16,(A32+B32+Q32)*C32*0.0628))))))),IF(A32="","",IF(K32=26,(A32+B32+Q32)*C32*0.211,IF(K32=24,(A32+B32+Q32)*C32*0.211,IF(K32=22,(A32+B32+Q32)*C32*0.258,IF(K32=20,(A32+B32+Q32)*C32*0.304,IF(K32=18,(A32+B32+Q32)*C32*0.395,IF(K32=16,(A32+B32+Q32)*C32*0.487)))))))) | M32: =IF(D32=1,0.5,IF(D32=2,"1 F",IF(D32=21,"1 R",IF(D32=3,2,"")))) | N32: =IF(M32="","",IF($N$4="M",(A32+B32+Q32)*C32*0.022,(A32+B32+Q32)*C32*0.17)) | O32: =IF(D32=4,1,IF(D32=5,2,"")) | P32: =IF(O32="","",IF($N$4="M",IF(O32=1,(A32+B32+Q32)*C32*0.022*1.1,(A32+B32+Q32)*C32*0.022*1.15),IF(O32=1,(A32+B32+Q32)*C32*0.17*1.1,(A32+B32+Q32)*C32*0.17*1.15))) | Q32: =IF($N$4="M",IF(A32="","",IF(D32=1,50,IF(D32=2,100,IF(D32=21,100,IF(D32=3,200,0))))),IF(A32="","",IF(D32=1,2,IF(D32=2,4,IF(D32=21,4,IF(D32=3,8,0)))))) | R32: =COUNTIF(G32:J32,7) -> 0 | S32: =IF(A32="","",IF($N$4="M",A32*B32*0.000011111*R32*1.5,A32*B32/144*R32*1.5)) | T32: =COUNTIF(G32:J32,71) -> 0 | U32: =IF(A32="","",IF($N$4="M",A32*B32*0.000011111*T32*1.5,A32*B32/144*T32*1.5)) | V32: =COUNTIF(G32:J32,8) -> 0 | W32: =IF(A32="","",IF($N$4="M",(A32+B32)*2*0.0032808*V32,(A32+B32)*2*V32/12)) | X32: =COUNTIF(G32:J32,81) -> 0 | Y32: =IF(A32="","",IF($N$4="M",(A32+B32)*2*0.0032808*X32,(A32+B32)*2*X32/12)) | Z32: =COUNTIF(G32:J32,9) -> 0 | AA32: =COUNTIF(G32:J32,10) -> 0 | AB32: =IF(A32="","",IF($N$4="M",(A32+B32)*2*0.0032808*AA32,(A32+B32)*2*AA32/12)) | AC32: =COUNTIF(G32:J32,100) -> 0 | AE32: =COUNTIF(G32:J32,11) -> 0 | AF32: =IF(A32="","",IF($N$4="M",A32*B32*0.000011111*AE32,A32*B32/144*AE32)) | AG32: =COUNTIF(G32:J32,111) -> 0 | AH32: =IF(A32="","",IF($N$4="M",A32*B32*0.000011111*AG32,A32*B32/144*AG32)) | AI32: =COUNTIF(G32:J32,12) -> 0 | AJ32: =IF(A32="","",IF($N$4="M",A32*B32*0.000011111*AI32,A32*B32/144*AI32)) | AK32: =COUNTIF(G32:J32,13) -> 0 | AL32: =COUNTIF(G32:J32,131) -> 0 | AM32: =IF(A32="","",IF($N$4="M",A32*B32*0.000011111*AL32,A32*B32/144*AL32)) | AN32: =COUNTIF(G32:J32,14) -> 0 | AO32: =IF(A32="","",IF($N$4="M",A32*B32*0.000011111*AN32,A32*B32/144*AN32)) | AP32: =COUNTIF(G32:J32,141) -> 0 | AQ32: =IF(A32="","",IF($N$4="M",A32*B32*0.000011111*AP32,A32*B32/144*AP32)) | AR32: =COUNTIF(G32:J32,15) -> 0 | AS32: =COUNTIF(G32:J32,16) -> 0 | AT32: =IF(A32="","",IF($N$4="M",A32*B32*0.000011111*AS32,A32*B32/144*AS32)) | AU32: =IF(D32=61,C32,0) -> 0 | AV32: =IF(D32=61,L32,0) -> 0 | AW32: =IF(A32="","",(C32-AU32)) | AX32: =IF(A32="","",(L32-AV32))
A33: 150 | B33: 150 | C33: 0 | F33: HA | G33: 13 | H33: 13 | I33: 13 | J33: 13 | K33: =IF($N$4="M",IF(A33="","",IF(D33=6,16,IF(A33<=$M$5,26,IF(A33<=$M$6,24,IF(A33<=$M$7,22,IF(A33<=$M$8,20,18)))))),IF(A33="","",IF(D33=6,16,IF(A33<=$P$5,26,IF(A33<=$P$6,24,IF(A33<=$P$7,22,IF(A33<=$P$8,20,18))))))) | L33: =IF($N$4="M",IF(A33="","",IF(K33=26,(A33+B33+Q33)*C33*0.02739,IF(K33=24,(A33+B33+Q33)*C33*0.02739,IF(K33=22,(A33+B33+Q33)*C33*0.0333,IF(K33=20,(A33+B33+Q33)*C33*0.0393,IF(K33=18,(A33+B33+Q33)*C33*0.0511,IF(K33=16,(A33+B33+Q33)*C33*0.0628))))))),IF(A33="","",IF(K33=26,(A33+B33+Q33)*C33*0.211,IF(K33=24,(A33+B33+Q33)*C33*0.211,IF(K33=22,(A33+B33+Q33)*C33*0.258,IF(K33=20,(A33+B33+Q33)*C33*0.304,IF(K33=18,(A33+B33+Q33)*C33*0.395,IF(K33=16,(A33+B33+Q33)*C33*0.487)))))))) | M33: =IF(D33=1,0.5,IF(D33=2,"1 F",IF(D33=21,"1 R",IF(D33=3,2,"")))) | N33: =IF(M33="","",IF($N$4="M",(A33+B33+Q33)*C33*0.022,(A33+B33+Q33)*C33*0.17)) | O33: =IF(D33=4,1,IF(D33=5,2,"")) | P33: =IF(O33="","",IF($N$4="M",IF(O33=1,(A33+B33+Q33)*C33*0.022*1.1,(A33+B33+Q33)*C33*0.022*1.15),IF(O33=1,(A33+B33+Q33)*C33*0.17*1.1,(A33+B33+Q33)*C33*0.17*1.15))) | Q33: =IF($N$4="M",IF(A33="","",IF(D33=1,50,IF(D33=2,100,IF(D33=21,100,IF(D33=3,200,0))))),IF(A33="","",IF(D33=1,2,IF(D33=2,4,IF(D33=21,4,IF(D33=3,8,0)))))) | R33: =COUNTIF(G33:J33,7) -> 0 | S33: =IF(A33="","",IF($N$4="M",A33*B33*0.000011111*R33*1.5,A33*B33/144*R33*1.5)) | T33: =COUNTIF(G33:J33,71) -> 0 | U33: =IF(A33="","",IF($N$4="M",A33*B33*0.000011111*T33*1.5,A33*B33/144*T33*1.5)) | V33: =COUNTIF(G33:J33,8) -> 0 | W33: =IF(A33="","",IF($N$4="M",(A33+B33)*2*0.0032808*V33,(A33+B33)*2*V33/12)) | X33: =COUNTIF(G33:J33,81) -> 0 | Y33: =IF(A33="","",IF($N$4="M",(A33+B33)*2*0.0032808*X33,(A33+B33)*2*X33/12)) | Z33: =COUNTIF(G33:J33,9) -> 0 | AA33: =COUNTIF(G33:J33,10) -> 0 | AB33: =IF(A33="","",IF($N$4="M",(A33+B33)*2*0.0032808*AA33,(A33+B33)*2*AA33/12)) | AC33: =COUNTIF(G33:J33,100) -> 0 | AE33: =COUNTIF(G33:J33,11) -> 0 | AF33: =IF(A33="","",IF($N$4="M",A33*B33*0.000011111*AE33,A33*B33/144*AE33)) | AG33: =COUNTIF(G33:J33,111) -> 0 | AH33: =IF(A33="","",IF($N$4="M",A33*B33*0.000011111*AG33,A33*B33/144*AG33)) | AI33: =COUNTIF(G33:J33,12) -> 0 | AJ33: =IF(A33="","",IF($N$4="M",A33*B33*0.000011111*AI33,A33*B33/144*AI33)) | AK33: =COUNTIF(G33:J33,13) -> 0 | AL33: =COUNTIF(G33:J33,131) -> 0 | AM33: =IF(A33="","",IF($N$4="M",A33*B33*0.000011111*AL33,A33*B33/144*AL33)) | AN33: =COUNTIF(G33:J33,14) -> 0 | AO33: =IF(A33="","",IF($N$4="M",A33*B33*0.000011111*AN33,A33*B33/144*AN33)) | AP33: =COUNTIF(G33:J33,141) -> 0 | AQ33: =IF(A33="","",IF($N$4="M",A33*B33*0.000011111*AP33,A33*B33/144*AP33)) | AR33: =COUNTIF(G33:J33,15) -> 0 | AS33: =COUNTIF(G33:J33,16) -> 0 | AT33: =IF(A33="","",IF($N$4="M",A33*B33*0.000011111*AS33,A33*B33/144*AS33)) | AU33: =IF(D33=61,C33,0) -> 0 | AV33: =IF(D33=61,L33,0) -> 0 | AW33: =IF(A33="","",(C33-AU33)) | AX33: =IF(A33="","",(L33-AV33))
A34: 150 | B34: 150 | C34: 0 | F34: HA | G34: 10 | H34: 10 | K34: =IF($N$4="M",IF(A34="","",IF(D34=6,16,IF(A34<=$M$5,26,IF(A34<=$M$6,24,IF(A34<=$M$7,22,IF(A34<=$M$8,20,18)))))),IF(A34="","",IF(D34=6,16,IF(A34<=$P$5,26,IF(A34<=$P$6,24,IF(A34<=$P$7,22,IF(A34<=$P$8,20,18))))))) | L34: =IF($N$4="M",IF(A34="","",IF(K34=26,(A34+B34+Q34)*C34*0.02739,IF(K34=24,(A34+B34+Q34)*C34*0.02739,IF(K34=22,(A34+B34+Q34)*C34*0.0333,IF(K34=20,(A34+B34+Q34)*C34*0.0393,IF(K34=18,(A34+B34+Q34)*C34*0.0511,IF(K34=16,(A34+B34+Q34)*C34*0.0628))))))),IF(A34="","",IF(K34=26,(A34+B34+Q34)*C34*0.211,IF(K34=24,(A34+B34+Q34)*C34*0.211,IF(K34=22,(A34+B34+Q34)*C34*0.258,IF(K34=20,(A34+B34+Q34)*C34*0.304,IF(K34=18,(A34+B34+Q34)*C34*0.395,IF(K34=16,(A34+B34+Q34)*C34*0.487)))))))) | M34: =IF(D34=1,0.5,IF(D34=2,"1 F",IF(D34=21,"1 R",IF(D34=3,2,"")))) | N34: =IF(M34="","",IF($N$4="M",(A34+B34+Q34)*C34*0.022,(A34+B34+Q34)*C34*0.17)) | O34: =IF(D34=4,1,IF(D34=5,2,"")) | P34: =IF(O34="","",IF($N$4="M",IF(O34=1,(A34+B34+Q34)*C34*0.022*1.1,(A34+B34+Q34)*C34*0.022*1.15),IF(O34=1,(A34+B34+Q34)*C34*0.17*1.1,(A34+B34+Q34)*C34*0.17*1.15))) | Q34: =IF($N$4="M",IF(A34="","",IF(D34=1,50,IF(D34=2,100,IF(D34=21,100,IF(D34=3,200,0))))),IF(A34="","",IF(D34=1,2,IF(D34=2,4,IF(D34=21,4,IF(D34=3,8,0)))))) | R34: =COUNTIF(G34:J34,7) -> 0 | S34: =IF(A34="","",IF($N$4="M",A34*B34*0.000011111*R34*1.5,A34*B34/144*R34*1.5)) | T34: =COUNTIF(G34:J34,71) -> 0 | U34: =IF(A34="","",IF($N$4="M",A34*B34*0.000011111*T34*1.5,A34*B34/144*T34*1.5)) | V34: =COUNTIF(G34:J34,8) -> 0 | W34: =IF(A34="","",IF($N$4="M",(A34+B34)*2*0.0032808*V34,(A34+B34)*2*V34/12)) | X34: =COUNTIF(G34:J34,81) -> 0 | Y34: =IF(A34="","",IF($N$4="M",(A34+B34)*2*0.0032808*X34,(A34+B34)*2*X34/12)) | Z34: =COUNTIF(G34:J34,9) -> 0 | AA34: =COUNTIF(G34:J34,10) -> 0 | AB34: =IF(A34="","",IF($N$4="M",(A34+B34)*2*0.0032808*AA34,(A34+B34)*2*AA34/12)) | AC34: =COUNTIF(G34:J34,100) -> 0 | AE34: =COUNTIF(G34:J34,11) -> 0 | AF34: =IF(A34="","",IF($N$4="M",A34*B34*0.000011111*AE34,A34*B34/144*AE34)) | AG34: =COUNTIF(G34:J34,111) -> 0 | AH34: =IF(A34="","",IF($N$4="M",A34*B34*0.000011111*AG34,A34*B34/144*AG34)) | AI34: =COUNTIF(G34:J34,12) -> 0 | AJ34: =IF(A34="","",IF($N$4="M",A34*B34*0.000011111*AI34,A34*B34/144*AI34)) | AK34: =COUNTIF(G34:J34,13) -> 0 | AL34: =COUNTIF(G34:J34,131) -> 0 | AM34: =IF(A34="","",IF($N$4="M",A34*B34*0.000011111*AL34,A34*B34/144*AL34)) | AN34: =COUNTIF(G34:J34,14) -> 0 | AO34: =IF(A34="","",IF($N$4="M",A34*B34*0.000011111*AN34,A34*B34/144*AN34)) | AP34: =COUNTIF(G34:J34,141) -> 0 | AQ34: =IF(A34="","",IF($N$4="M",A34*B34*0.000011111*AP34,A34*B34/144*AP34)) | AR34: =COUNTIF(G34:J34,15) -> 0 | AS34: =COUNTIF(G34:J34,16) -> 0 | AT34: =IF(A34="","",IF($N$4="M",A34*B34*0.000011111*AS34,A34*B34/144*AS34)) | AU34: =IF(D34=61,C34,0) -> 0 | AV34: =IF(D34=61,L34,0) -> 0 | AW34: =IF(A34="","",(C34-AU34)) | AX34: =IF(A34="","",(L34-AV34))
